Workbook

Sheet Brand Experience & Activation
A1: # | B1: Tier | C1: Campaign | D1: Brand | E1: Product/Service | F1: Agency | G1: Country | H1: Subcategory | I1: Image URL | J1: YouTube ID | K1: Campaign Group | L1: Entry URL
A2: 1 | B2: Grand Prix | C2: Caption with Intention | D2: Academy of Motion Picture Arts & Sciences / Chicago Hearing Society | E2: Closed Captioning | F2: FCB Chicago | G2: United States | H2: A05 - Media/Entertainment | I2: https://ascentialcdn.filespin.io/api/v1/conversion/ae51c3c9f04d452e914dba0555d8b029 | J2: F48khKZhKHM | L2: https://www.lovethework.com/work/entries/caption-with-intention-746864
A3: 2 | B3: Gold | C3: ADS Cover Rents | D3: Brahma | E3: Beer | F3: Africa Creative DDB Sao Paulo | G3: Brazil | H3: D02 - Guerrilla Marketing | I3: https://ascentialcdn.filespin.io/api/v1/conversion/17a255fb4a7d40d79616736a9ee7914c | J3: 8R2TckoklzM | L3: https://www.lovethework.com/work/entries/ads-cover-rents-747640
A4: 3 | B4: Gold | C4: Drops of Hope | D4: Kimberly-Clark | E4: Poise | F4: FCB New York | G4: United States | H4: A01 - Consumer Goods | I4: https://ascentialcdn.filespin.io/api/v1/conversion/6b9aa5b716a6476ca0f016a3c2a0dd62 | J4: MnF0kip489Y | L4: https://www.lovethework.com/work/entries/drops-of-hope-748188
A5: 4 | B5: Gold | C5: Drops of Hope | D5: Kimberly-Clark | E5: Poise | F5: FCB New York | G5: United States | H5: E07 - Corporate Purpose | I5: https://ascentialcdn.filespin.io/api/v1/conversion/b6b3814255234c3596fcb99868c0fbb7 | J5: MnF0kip489Y | L5: https://www.lovethework.com/work/entries/drops-of-hope-748188
A6: 5 | B6: Gold | C6: Fictional Insurance | D6: RCN/Prime | E6: Insurance | F6: DDB Colombia Bogota | G6: Colombia | H6: C03 - Customer Acquisition | I6: https://ascentialcdn.filespin.io/api/v1/conversion/8466955db96a4c52b6813e12a8c63226 | J6: OctiVcwaiXI | L6: https://www.lovethework.com/work/entries/fictional-insurance-747450
A7: 6 | B7: Gold | C7: Gulf of Mexico (Bar) | D7: Tecate | E7: Tecate Light | F7: LePub Mexico City | G7: Mexico | H7: E01 - Local Brand | I7: https://ascentialcdn.filespin.io/api/v1/conversion/afa88aa8421b41a18c68b9863bb6926c | J7: TFbAS7weMR8 | L7: https://www.lovethework.com/work/entries/gulf-of-mexico-bar-747778
A8: 7 | B8: Gold | C8: Lessons of Shame | D8: World Vision | E8: Institutional | F8: Havas Costa Rica | G8: Costa Rica | H8: A07 - Not-for-Profit | I8: https://ascentialcdn.filespin.io/api/v1/conversion/71112ff9b2324f9b8f9338c809483684 | J8: YrNH2-6vqZo | L8: https://www.lovethework.com/work/entries/lessons-of-shame-746863
A9: 8 | B9: Gold | C9: Lucky Yatra | D9: Indian Railways | E9: Railway Service | F9: FCB India Mumbai | G9: India | H9: C03 - Customer Acquisition | I9: https://ascentialcdn.filespin.io/api/v1/conversion/2e252d74f69d4889b7886d241255186a | J9: IYJlZRbvMEw | L9: https://www.lovethework.com/work/entries/lucky-yatra-747400
A10: 9 | B10: Gold | C10: Price Packs | D10: Penny | E10: Food/Non-Food | F10: Serviceplan Germany | G10: Germany | H10: E08 - Market Disruption | I10: https://ascentialcdn.filespin.io/api/v1/conversion/67b6df2a0fe64deeb274c91d50040c54 | J10: cnAXR4lk6R0 | L10: https://www.lovethework.com/work/entries/price-packs-748536
A11: 10 | B11: Gold | C11: The Kimberly Price | D11: Plaza Vea | E11: Plaza Vea | F11: Fahrenheit DDB Lima | G11: Peru | H11: B01 - Social Engagement | I11: https://ascentialcdn.filespin.io/api/v1/conversion/dd37e163320440a58d69763c047eec03 | J11: pPAGka7S4_o | L11: https://www.lovethework.com/work/entries/the-kimberly-price-746894
A12: 11 | B12: Gold | C12: Winter Takes on Colors | D12: McDonald's Polska | E12: Drwala Burger | F12: DDB Warsaw | G12: Poland | H12: C01 - Customer Retail | I12: https://ascentialcdn.filespin.io/api/v1/conversion/4ff9778738a146549164d3153acb8808 | J12: qcSHtBgAB6o | L12: https://www.lovethework.com/work/entries/winter-takes-on-colors-747343
A13: 12 | B13: Silver | C13: 855-How-to-Quit-(Opioids) | D13: Anzen Health | E13: 855-How-to-Quit-Helpline | F13: Serviceplan Germany | G13: Germany | H13: A02 - Healthcare | I13: https://ascentialcdn.filespin.io/api/v1/conversion/650a86946acf45c9946d15c4d5f10c86 | J13: I_xvPLZ9DDk | L13: https://www.lovethework.com/work/entries/855-how-to-quit-opioids-746670
... A68: 67 | B68: Bronze | C68: Worst Children's Library | D68: Samsung | E68: Samsung | F68: DDB New Zealand Auckland | G68: New Zealand | H68: E04 - Social Behaviour | I68: https://ascentialcdn.filespin.io/api/v1/conversion/24a4ad960f3c4ac8a1a86823848e8d17 | J68: 2B2-joqRoHc | L68: https://www.lovethework.com/work/entries/worst-childrens-library-748079

Sheet Audio & Radio
A1: # | B1: Tier | C1: Campaign | D1: Brand | E1: Product/Service | F1: Agency | G1: Country | H1: Subcategory | I1: Image URL | J1: YouTube ID | K1: Campaign Group | L1: Entry URL
A2: 1 | B2: Grand Prix | C2: One Second Ads | D2: Budweiser | E2: Beer | F2: Africa Creative DDB | G2: Brazil | H2: B01 - Use of Music | I2: digital-presentation-images/audio-and-radio-budweiser-one-second-ads.webp | J2: RpvlshoKIrE | L2: https://www.lovethework.com/work/entries/one-second-ads-741948
A3: 2 | B3: Gold | C3: Name This Oreo | D3: Oreo | E3: Oreo | F3: VML | G3: United States | H3: A03 - Voice Activation | I3: digital-presentation-images/audio-and-radio-oreo-name-this-oreo.webp | J3: hRp6cBmbfIw | L3: https://www.lovethework.com/work/entries/name-this-oreo-741853
A4: 3 | B4: Gold | C4: One Second Ads | D4: Budweiser | E4: Beer | F4: Africa Creative DDB | G4: Brazil | H4: A06 - Audio-Led Creativity | I4: digital-presentation-images/audio-and-radio-budweiser-one-second-ads.webp | J4: RpvlshoKIrE | L4: https://www.lovethework.com/work/entries/one-second-ads-741888
A5: 4 | B5: Gold | C5: The Second Release | D5: Billboard Arabia | E5: Billboard Magazine | F5: SRMG Labs | G5: Saudi Arabia | H5: C03 - Single-Market Campaign | I5: digital-presentation-images/audio-and-radio-billboard-arabia-the-second-release.webp | J5: gD1XqvQaMR0 | L5: https://www.lovethework.com/work/entries/the-second-release-742149
A6: 5 | B6: Silver | C6: Name This Oreo | D6: Oreo | E6: Oreo | F6: VML | G6: United States | H6: A01 - Use of Audio & Radio as a Medium | I6: digital-presentation-images/audio-and-radio-oreo-name-this-oreo.webp | J6: hRp6cBmbfIw | L6: https://www.lovethework.com/work/entries/name-this-oreo-741778
A7: 6 | B7: Silver | C7: Fishermen Storytellers | D7: Corona | E7: Beer | F7: Africa Creative DDB | G7: Brazil | H7: A04 - Branded Content/Podcasts | I7: digital-presentation-images/audio-and-radio-corona-fishermen-storytellers.webp | J7: LDbcqtL9zP8 | L7: https://www.lovethework.com/work/entries/fishermen-storytellers-764514
A8: 7 | B8: Silver | C8: 1. High Energy Intern | D8: Fusion Energy Drink | E8: Energy Drink | F8: David | G8: Spain | H8: B03 - Script | I8: https://ascentialcdn.filespin.io/api/v1/storyboard/846afe3e468240929823119e42cf3b99/storyboard_000008.jpg | J8: vimeo:1093833122 | L8: https://www.lovethework.com/work/entries/1-high-energy-intern-762404
A9: 8 | B9: Silver | C9: Chill Enough | D9: Coors Light | E9: Coors Light | F9: Alma Advertising Agency | G9: United States | H9: B04 - Casting & Performance | I9: digital-presentation-images/audio-and-radio-coors-light-chill-enough.webp | J9: BqqqBYEADPg | L9: https://www.lovethework.com/work/entries/chill-enough-762433
A10: 9 | B10: Silver | C10: Burger to King | D10: Burger King | E10: Burger King | F10: Happiness, an FCB Alliance | G10: Belgium | H10: C02 - Challenger Brand | I10: digital-presentation-images/audio-and-radio-burger-king-burger-to-king.webp | J10: RQVaoU4CGRk | L10: https://www.lovethework.com/work/entries/burger-to-king-763482
A11: 10 | B11: Silver | C11: The Second Release | D11: Billboard Arabia | E11: Billboard Magazine | F11: SRMG Labs | G11: Saudi Arabia | H11: C04 - Social Behaviour | I11: digital-presentation-images/audio-and-radio-billboard-arabia-the-second-release.webp | J11: gD1XqvQaMR0 | L11: https://www.lovethework.com/work/entries/the-second-release-742142
A12: 11 | B12: Silver | C12: From Hurt to Hit | D12: Brahma | E12: Beer | F12: Africa Creative DDB | G12: Brazil | H12: C05 - Use of Humour | I12: https://ascentialcdn.filespin.io/api/v1/conversion/2c4c0601d34e42cf931304cf072f6fa8 | J12: t10NTUNmF8c | L12: https://www.lovethework.com/work/entries/from-hurt-to-hit-742107
A13: 12 | B13: Silver | C13: Me Feat. Me | D13: Nosotras | E13: Nosotras | F13: DDB Chile | G13: Chile | H13: C09 - Cultural Engagement | I13: https://ascentialcdn.filespin.io/api/v1/conversion/a6ac5c5dd4fc4487966ae01ac52f95ff | J13: KBcSEzHf5DA | L13: https://www.lovethework.com/work/entries/me-feat-me-742031
... A22: 21 | B22: Bronze | C22: Sounds Right | D22: Museum for the United Nations - UN Live, Spotify | E22: Music | F22: AKQA | G22: Denmark | H22: C07 - Corporate Purpose & Social Responsibility | I22: digital-presentation-images/audio-and-radio-museum-for-the-united-nations-sounds-right.webp | J22: 5newTxSZ9bU | L22: https://www.lovethework.com/work/entries/sounds-right-759882

Sheet Film
A1: # | B1: Tier | C1: Campaign | D1: Brand | E1: Product/Service | F1: Agency | G1: Country | H1: Subcategory | I1: Image URL | J1: YouTube ID | K1: Campaign Group | L1: Entry URL
A2: 1 | B2: Grand Prix | C2: Paris Paralympics 2024: Considering What? | D2: CHANNEL 4 | E2: CHANNEL 4 | F2: CHANNEL 4 | G2: United Kingdom | H2: A05 - Media/Entertainment | I2: digital-presentation-images/film-channel-4-paris-paralympic-2024-considering-what.webp | J2: bUs_mNTNwvE | L2: https://www.lovethework.com/work/entries/paris-paralympics-2024-considering-what-738686
A3: 2 | B3: Grand Prix | C3: The Final Copy of Ilon Specht | D3: L'ORÉAL PARIS | E3: L'ORÉAL PARIS | F3: McCANN | G3: France | H3: F07 - Corporate Purpose & Social Responsibility | I3: digital-presentation-images/film-loreal-paris-the-final-copy-of-ilona-specht.webp | J3: -4o8bCc6-GM | L3: https://www.lovethework.com/work/entries/the-final-copy-of-ilon-specht-739568
A4: 3 | B4: Gold | C4: Find Your Friends | D4: APPLE | E4: PRECISION FINDING | F4: APPLE | G4: United States | H4: B01 - Consumer Goods | I4: digital-presentation-images/film-apple-find-your-friends.webp | J4: LO4wamMlCKQ | L4: https://www.lovethework.com/work/entries/find-your-friends-738592
A5: 4 | B5: Gold | C5: Never Just a Period | D5: BODYFORM | E5: BODYFORM | F5: AMV BBDO | G5: United Kingdom | H5: B02 - Healthcare | I5: digital-presentation-images/film-bodyform-never-just-a-period.webp | J5: EQW59KR3c4U | L5: https://www.lovethework.com/work/entries/never-just-a-period-738863
A6: 5 | B6: Gold | C6: Let There Be Cake | D6: KFC THAILAND | E6: KFC 40TH | F6: BANANAS | G6: South Africa | H6: B04 - Travel, Leisure, Retail, Restaurants & Fast-Food Chains | I6: https://ascentialcdn.filespin.io/api/v1/storyboard/880f481b580e4ddbb51427137d8c2233/storyboard_000008.jpg | J6: YDaAgeyVXiw | L6: https://www.lovethework.com/work/entries/let-there-be-cake-759113
A7: 6 | B7: Gold | C7: The Last Birthday | D7: ASSOCIATION VALENTIN HAÜY | E7: Non Profit Organization - Defense of the Rights of Blind and Visually Impaired People | F7: JOSIANE | G7: France | H7: B07 - Not-For-Profit / Charity / Government | I7: digital-presentation-images/film-association-valentin-hauy-the-last-birthday.webp | J7: E4mGmGE8fC0 | L7: https://www.lovethework.com/work/entries/the-last-birthday-739026
A8: 7 | B8: Gold | C8: Telstra - Better on a Better Network | D8: TELSTRA | E8: TELSTRA | F8: BEAR MEETS EAGLE ON FIRE | G8: Australia | H8: F03 - Single-Market Campaign | I8: digital-presentation-images/film-telstra-telstra-better-on-a-better-network.webp | J8: L8wOtakkr28 | L8: https://www.lovethework.com/work/entries/telstra-better-on-a-better-network-739331
A9: 8 | B9: Gold | C9: The Best Place in the World to Have Herpes | D9: NEW ZEALAND HERPES FOUNDATION | E9: NEW ZEALAND HERPES FOUNDATION | F9: FINCH | G9: Australia | H9: F05 - Use of Humour | I9: digital-presentation-images/film-new-zealand-herpes-foundation-the-best-place-in-the-world-to-have-herpes.webp | J9: DvaU3-VCk8I | L9: https://www.lovethework.com/work/entries/the-best-place-in-the-world-to-have-herpes-739431
A10: 9 | B10: Gold | C10: Brian Cox Goes to College | D10: UBER ONE | E10: UBER ONE FOR STUDENTS | F10: SPECIAL | G10: United States | H10: F05 - Use of Humour | I10: digital-presentation-images/film-uber-one-brian-cox-goes-to-college.webp | J10: vimeo:1035756667 | L10: https://www.lovethework.com/work/entries/brian-cox-goes-to-college-739411
A11: 10 | B11: Gold | C11: Group Therapy | D11: AXA | E11: AXA | F11: VML | G11: France | H11: F05 - Use of Humour | I11: digital-presentation-images/film-axa-group-therapy.webp | J11: cH8-sNMfrOM | L11: https://www.lovethework.com/work/entries/group-therapy-739424
A12: 11 | B12: Silver | C12: Flock | D12: APPLE | E12: IPHONE | F12: TBWA\MEDIA ARTS LAB | G12: United States | H12: A01 - Consumer Goods | I12: digital-presentation-images/film-apple-flock.webp | J12: jom8zBix-4c | L12: https://www.lovethework.com/work/entries/flock-738495
A13: 12 | B13: Silver | C13: Jordan Can't Ban Greatness | D13: NIKE | E13: NIKE | F13: WIEDEN+KENNEDY | G13: United States | H13: A01 - Consumer Goods | I13: digital-presentation-images/film-nike-jordan-cant-ban-greatness.webp | J13: L-upphAEYGc | L13: https://www.lovethework.com/work/entries/jordan-cant-ban-greatness-738501
... A53: 52 | B53: Bronze | C53: Skin | D53: RAÇA MAGAZINE | E53: INSTITUTIONAL | F53: LEPUB | G53: Brazil | H53: F09 - Cultural Engagement | I53: digital-presentation-images/film-raca-magazine-skin.webp | J53: vimeo:1088284685 | L53: https://www.lovethework.com/work/entries/skin-739661

Sheet Outdoor
A1: # | B1: Tier | C1: Campaign | D1: Brand | E1: Product/Service | F1: Agency | G1: Country | H1: Subcategory | I1: Image URL | J1: YouTube ID | K1: Campaign Group | L1: Entry URL
A2: 1 | B2: Grand Prix | C2: Crowd | D2: KitKat | E2: KitKat | F2: VML | G2: Czech Republic | H2: A01 - Consumer Goods | I2: https://ascentialcdn.filespin.io/api/v1/conversion/6dc8ee87b55d449f88c8f8a0868b533a | J2: ByGNQ3wEbEY | K2: kitkat-a01-consumer-goods | L2: https://www.lovethework.com/work/entries/crowd-740225
A3: 2 | B3: Grand Prix | C3: Public Transport | D3: KitKat | E3: KitKat | F3: VML | G3: Czech Republic | H3: A01 - Consumer Goods | I3: https://ascentialcdn.filespin.io/api/v1/conversion/9b1fc196d863402282277d81f4bdf031 | J3: ByGNQ3wEbEY | K3: kitkat-a01-consumer-goods | L3: https://www.lovethework.com/work/entries/public-transport-758659
A4: 3 | B4: Grand Prix | C4: Street | D4: KitKat | E4: KitKat | F4: VML | G4: Czech Republic | H4: A01 - Consumer Goods | I4: https://ascentialcdn.filespin.io/api/v1/conversion/ad97fbb0d50649118006eac4d5a902a7 | J4: ByGNQ3wEbEY | K4: kitkat-a01-consumer-goods | L4: https://www.lovethework.com/work/entries/street-758667
A5: 4 | B5: Grand Prix | C5: Olympic Games Opening Ceremony Paris 2024 | D5: Paris 2024 | E5: Paris 2024 | F5: PANAME 24 | G5: France | H5: C04 - Live Advertising and Events | I5: https://ascentialcdn.filespin.io/api/v1/conversion/60aa1888e5b6444381b060dc1801de84 | J5: t8o4ulxT1Cc | L5: https://www.lovethework.com/work/entries/olympic-games-opening-ceremony-paris-2024-740923
A6: 5 | B6: Gold | C6: The Sip of Sanctuary | D6: Stella Artois | E6: Stella Artois | F6: GREY | G6: United Kingdom | H6: A01 - Consumer Goods | I6: https://ascentialcdn.filespin.io/api/v1/conversion/bc046e548975443980453424bc30515a | K6: stella-artois-philosophical | L6: https://www.lovethework.com/work/entries/the-sip-of-sanctuary-740333
A7: 6 | B7: Gold | C7: Protector of the Chalice | D7: Stella Artois | E7: Stella Artois | F7: GREY | G7: United Kingdom | H7: A01 - Consumer Goods | I7: https://ascentialcdn.filespin.io/api/v1/conversion/a33c9462c05d4330895b056745b6a602 | K7: stella-artois-philosophical | L7: https://www.lovethework.com/work/entries/protector-of-the-chalice-740342
A8: 7 | B8: Gold | C8: Happiness Within Chaos | D8: Stella Artois | E8: Stella Artois | F8: GREY | G8: United Kingdom | H8: A01 - Consumer Goods | I8: https://ascentialcdn.filespin.io/api/v1/conversion/882ea591b6fa40b29a529180b71afa65 | K8: stella-artois-philosophical | L8: https://www.lovethework.com/work/entries/happiness-within-chaos-740351
A9: 8 | B9: Gold | C9: Fries | D9: Heinz | E9: Heinz | F9: Wieden+Kennedy | G9: United Kingdom | H9: B01 - Consumer Goods | I9: https://ascentialcdn.filespin.io/api/v1/conversion/9e7a10af468b4293bb13624b6ac695d7 | J9: GR2NjU6fhZw | K9: heinz-b01-consumer-goods | L9: https://www.lovethework.com/work/entries/fries-740416
A10: 9 | B10: Gold | C10: Chips | D10: Heinz | E10: Heinz | F10: Wieden+Kennedy | G10: United Kingdom | H10: B01 - Consumer Goods | I10: https://ascentialcdn.filespin.io/api/v1/conversion/98502860304b486096f96cbacf35f7ac | J10: 9HpJtpvtrhs | K10: heinz-b01-consumer-goods | L10: https://www.lovethework.com/work/entries/chips-740534
A11: 10 | B11: Gold | C11: Toast | D11: Heinz | E11: Heinz | F11: Wieden+Kennedy | G11: United Kingdom | H11: B01 - Consumer Goods | I11: https://ascentialcdn.filespin.io/api/v1/conversion/19b79ceaf445400d88e358d61316e067 | J11: keOaQm6RpBg | K11: heinz-b01-consumer-goods | L11: https://www.lovethework.com/work/entries/toast-740549
A12: 11 | B12: Gold | C12: Scratch & Sniff | D12: Axe/Lynx | E12: Deodorant | F12: LOLA MullenLowe | G12: Spain | H12: C01 - Displays | I12: https://ascentialcdn.filespin.io/api/v1/conversion/a4189a00c22b49558f6796c1b0fdf90c | J12: L5RfU7Jmoug | L12: https://www.lovethework.com/work/entries/scratch-sniff-740665
A13: 12 | B13: Gold | C13: Shades of Red | D13: Coca-Cola | E13: Coca-Cola Company | F13: DAVID | G13: Spain | H13: C03 - Special Build | I13: https://ascentialcdn.filespin.io/api/v1/conversion/b9b1ac806434448cb6648aa308f263db | J13: 7kRgxEIhX38 | K13: coca-cola-shades-of-red | L13: https://www.lovethework.com/work/entries/shades-of-red-740785
A14: 13 | B14: Gold | C14: Missed Birthdays | D14: ITV X CALM | E14: ITV X CALM | F14: adam&eveDDB | G14: United Kingdom | H14: C04 - Live Advertising and Events | I14: https://ascentialcdn.filespin.io/api/v1/conversion/238b3e3f0aab4c3fa9adf2b23d50eab3 | J14: ifZVZ4fX4gg | L14: https://www.lovethework.com/work/entries/missed-birthdays-740958
A15: 14 | B15: Gold | C15: Tracking Bad Bunny | D15: Rimas Music | E15: Bad Bunny | F15: DDB Latina Puerto Rico | G15: Puerto Rico | H15: C05 - Interactive Experiences | I15: https://ascentialcdn.filespin.io/api/v1/conversion/8c433c0437494277a7cb3b8c1148b82c | J15: -3Aq3u6EJZ4 | L15: https://www.lovethework.com/work/entries/tracking-bad-bunny-759229
A16: 15 | B16: Gold | C16: Gulf of Mexico (Bar) | D16: Tecate | E16: Tecate Light | F16: LePub | G16: Mexico | H16: E01 - Local Brand | I16: https://ascentialcdn.filespin.io/api/v1/conversion/afa88aa8421b41a18c68b9863bb6926c | J16: TFbAS7weMR8 | L16: https://www.lovethework.com/work/entries/gulf-of-mexico-bar-741350
A17: 16 | B17: Gold | C17: Price Packs | D17: Penny | E17: Food/Non-Food | F17: Serviceplan Germany | G17: Germany | H17: E02 - Challenger Brand | I17: https://ascentialcdn.filespin.io/api/v1/conversion/67b6df2a0fe64deeb274c91d50040c54 | J17: cnAXR4lk6R0 | L17: https://www.lovethework.com/work/entries/price-packs-741243
A18: 17 | B18: Gold | C18: Lucky Yatra | D18: Indian Railways | E18: Railway Service | F18: FCB India | G18: India | H18: E04 - Social Behaviour | I18: https://ascentialcdn.filespin.io/api/v1/conversion/7771593e59654e55b2c0654f5d61ec8e | J18: IYJlZRbvMEw | L18: https://www.lovethework.com/work/entries/lucky-yatra-741463
A19: 18 | B19: Silver | C19: Windsurf | D19: Cornetto | E19: Cornetto Ice Cream | F19: LOLA MullenLowe | G19: Spain | H19: B01 - Consumer Goods | I19: https://ascentialcdn.filespin.io/api/v1/conversion/2f9ebcc7b9ec4ad9a4dcf79bd56fa88b | J19: hWhvFLwHOlE | K19: cornetto-b01-consumer-goods | L19: https://www.lovethework.com/work/entries/windsurf-740535
A20: 19 | B20: Silver | C20: Surfer | D20: Cornetto | E20: Cornetto Ice Cream | F20: LOLA MullenLowe | G20: Spain | H20: B01 - Consumer Goods | I20: https://ascentialcdn.filespin.io/api/v1/conversion/9ceaf650a007496f90b6d5670786b4df | J20: hWhvFLwHOlE | K20: cornetto-b01-consumer-goods | L20: https://www.lovethework.com/work/entries/surfer-740546
A21: 20 | B21: Silver | C21: Waves | D21: Cornetto | E21: Cornetto Ice Cream | F21: LOLA MullenLowe | G21: Spain | H21: B01 - Consumer Goods | I21: https://ascentialcdn.filespin.io/api/v1/conversion/35c567148f6e40e1a267849bde62ba92 | J21: hWhvFLwHOlE | K21: cornetto-b01-consumer-goods | L21: https://www.lovethework.com/work/entries/waves-740554
A22: 21 | B22: Silver | C22: Boat | D22: Cornetto | E22: Cornetto Ice Cream | F22: LOLA MullenLowe | G22: Spain | H22: B01 - Consumer Goods | I22: https://ascentialcdn.filespin.io/api/v1/conversion/3a177c8b37754037a19ddf0d99c858db | J22: hWhvFLwHOlE | K22: cornetto-b01-consumer-goods | L22: https://www.lovethework.com/work/entries/boat-740365
A23: 22 | B23: Silver | C23: Bundles of Joy OOH2 | D23: Burger King UK | E23: Whopper | F23: BBH | G23: United Kingdom | H23: B04 - Travel, Leisure, Retail, Restaurants & Fast-Food Chains | I23: digital-presentation-images/outdoor-burger-king-bundles-of-joy-ooh2.webp | J23: aVzEfsIC9KQ | K23: burger-king-uk-b04-travel-leisure-retail-restaurants-fast-food-chains | L23: https://www.lovethework.com/work/entries/bundles-of-joy-ooh2-740450
A24: 23 | B24: Silver | C24: Bundles of Joy OOH1 | D24: Burger King UK | E24: Whopper | F24: BBH | G24: United Kingdom | H24: B04 - Travel, Leisure, Retail, Restaurants & Fast-Food Chains | I24: digital-presentation-images/outdoor-burger-king-bundles-of-joy-ooh1.webp | J24: aVzEfsIC9KQ | K24: burger-king-uk-b04-travel-leisure-retail-restaurants-fast-food-chains | L24: https://www.lovethework.com/work/entries/bundles-of-joy-ooh1-740460
A25: 24 | B25: Silver | C25: Bundles of Joy OOH4 | D25: Burger King UK | E25: Whopper | F25: BBH | G25: United Kingdom | H25: B04 - Travel, Leisure, Retail, Restaurants & Fast-Food Chains | I25: digital-presentation-images/outdoor-burger-king-bundles-of-joy-ooh4.webp | J25: aVzEfsIC9KQ | K25: burger-king-uk-b04-travel-leisure-retail-restaurants-fast-food-chains | L25: https://www.lovethework.com/work/entries/bundles-of-joy-ooh4-740466
A26: 25 | B26: Silver | C26: Bundles of Joy OOH3 | D26: Burger King UK | E26: Whopper | F26: BBH | G26: United Kingdom | H26: B04 - Travel, Leisure, Retail, Restaurants & Fast-Food Chains | I26: digital-presentation-images/outdoor-burger-king-bundles-of-joy-ooh3.webp | J26: aVzEfsIC9KQ | K26: burger-king-uk-b04-travel-leisure-retail-restaurants-fast-food-chains | L26: https://www.lovethework.com/work/entries/bundles-of-joy-ooh3-762361
A27: 26 | B27: Silver | C27: 'Til I Died | D27: British Heart Foundation | E27: British Heart Foundation | F27: Saatchi & Saatchi | G27: United Kingdom | H27: C01 - Displays | I27: https://ascentialcdn.filespin.io/api/v1/conversion/7c797fcbd4784d318b810a3e30777a8a | J27: jB_R0uQ_qcg | L27: https://www.lovethework.com/work/entries/til-i-died-740701
A28: 27 | B28: Silver | C28: Winter Takes on Colors | D28: McDonald's Polska | E28: Drwala Burger (Limited Timed Offer) | F28: DDB Warsaw | G28: Poland | H28: C03 - Special Build | I28: https://ascentialcdn.filespin.io/api/v1/conversion/5c6b7faa74e6455a830e3ef1f22b78d7 | J28: qcSHtBgAB6o | L28: https://www.lovethework.com/work/entries/winter-takes-on-colors-740759
A29: 28 | B29: Silver | C29: Night Signals | D29: Chevrolet Dominican Republic | E29: Chevrolet | F29: Ogilvy Dominican Republic | G29: Dominican Republic | H29: C06 - Transit | I29: https://ascentialcdn.filespin.io/api/v1/conversion/08a2258d5d1348b1bc8f6014ff0c6655 | J29: XVCXMuUU9s8 | L29: https://www.lovethework.com/work/entries/night-signals-741104
A30: 29 | B30: Silver | C30: Speed Coupons | D30: Mercado Livre | E30: Mercado Livre | F30: GUT | G30: Brazil | H30: D01 - Standard Sites | I30: https://ascentialcdn.filespin.io/api/v1/conversion/7e353b967fd64b6692fd97647bd4fbd2 | J30: l3Sxq8LCXZA | L30: https://www.lovethework.com/work/entries/speed-coupons-741121
A31: 30 | B31: Silver | C31: Sun Reserve | D31: Corona | E31: Corona | F31: GREY | G31: Brazil | H31: D02 - Ambient Outdoor | I31: https://ascentialcdn.filespin.io/api/v1/conversion/652b705dcecc4cb7a72c76e4e22c80e5 | J31: 7i2fC6qJR2o | L31: https://www.lovethework.com/work/entries/sun-reserve-741012
A32: 31 | B32: Silver | C32: The Philharmonic Prints | D32: Berliner Philharmonie | E32: Berliner Philharmoniker | F32: Scholz & Friends | G32: Germany | H32: E01 - Local Brand | I32: https://ascentialcdn.filespin.io/api/v1/conversion/a41ca6a9e9454bb585e089d1abcf0187 | J32: 6JuPo6BNhqU | L32: https://www.lovethework.com/work/entries/the-philharmonic-prints-741191
A33: 32 | B33: Silver | C33: See Them for Real | D33: Musée de l'Armée | E33: Museum | F33: Buzzman | G33: France | H33: E02 - Challenger Brand | I33: https://ascentialcdn.filespin.io/api/v1/conversion/f23ad7b894c14298b819130d99bc560f | J33: vimeo:1162577214 | L33: https://www.lovethework.com/work/entries/see-them-for-real-741246
A34: 33 | B34: Silver | C34: Bumpboards | D34: Citroen | E34: Citroen | F34: BETC | G34: France | H34: E03 - Single-Market Campaign | I34: https://ascentialcdn.filespin.io/api/v1/conversion/51f7223ae6f6484caace1b6d0e8df74c | J34: Qh8iW06HWYI | L34: https://www.lovethework.com/work/entries/bumpboards-741287
A35: 34 | B35: Silver | C35: Balikbayan Magic: Philippine Oriental Food Market | D35: Coca-Cola | E35: Coca-Cola | F35: VML | G35: Canada | H35: E04 - Social Behaviour | I35: digital-presentation-images/outdoor-coca-cola-balikbayan-magic-philippine-oriental-food-market.webp | J35: 8WbE3jyFeM8 | L35: https://www.lovethework.com/work/entries/balikbayan-magic-philippine-oriental-food-market-741455
A36: 35 | B36: Silver | C36: Meet Me at the Coke Sign | D36: Coca-Cola | E36: Coca-Cola | F36: Ogilvy | G36: Australia | H36: E04 - Social Behaviour | I36: https://ascentialcdn.filespin.io/api/v1/conversion/e4e51d450eb8458dab81e55d80f5d56b | J36: V2RVAsIFjF0 | L36: https://www.lovethework.com/work/entries/meet-me-at-the-coke-sign-741472
A37: 36 | B37: Silver | C37: Nature Shapes Britannia | D37: Britannia Industries Ltd. | E37: Britannia Sustainability | F37: Talented | G37: India | H37: E06 - Breakthrough on a Budget | I37: https://ascentialcdn.filespin.io/api/v1/conversion/716b17d07a0d40d2b7b2a29d2ae9e171 | J37: dEC4Wo3ZlXQ | L37: https://www.lovethework.com/work/entries/nature-shapes-britannia-741532
A38: 37 | B38: Silver | C38: Too Yumm to Cheer\! | D38: Too Yumm\! | E38: Too Yumm\! | F38: FCB Kinnect | G38: India | H38: E06 - Breakthrough on a Budget | I38: https://ascentialcdn.filespin.io/api/v1/conversion/cb9c8fa9b4464dc6bdc84535bb7991d5 | J38: 2Kf-xAN5WCI | L38: https://www.lovethework.com/work/entries/too-yumm-to-cheer-741592
... A44: 43 | B44: Bronze | C44: 'The Shining' | D44: Coca-Cola | E44: Coca-Cola | F44: VML | G44: United States | H44: A01 - Consumer Goods | I44: https://ascentialcdn.filespin.io/api/v1/conversion/44405bf6f33b4e919c5b283211199392 | J44: vimeo:1124237531 | L44: https://www.lovethework.com/work/entries/the-shining-740263
A45: 44 | B45: Bronze | C45: Mimi's Red | D45: Coca-Cola | E45: Coca-Cola Company | F45: DAVID | G45: Spain | H45: A01 - Consumer Goods | I45: https://ascentialcdn.filespin.io/api/v1/conversion/476f91b3c4024d889f9c5a3071d2af7f | J45: ELBlWKeEqQQ | K45: coca-cola-shades-of-red | L45: https://www.lovethework.com/work/entries/mimis-red-740318
...

Sheet Design
A1: # | B1: Tier | C1: Campaign | D1: Brand | E1: Product/Service | F1: Agency | G1: Country | H1: Subcategory | I1: Image URL | J1: YouTube ID | K1: Campaign Group | L1: Entry URL
A2: 1 | B2: Grand Prix | C2: Caption with Intention | D2: Academy of Motion Picture Arts & Sciences / Chicago Hearing Society | E2: Closed Captioning | F2: FCB Chicago | G2: United States | H2: B01 - Inclusive Design | I2: https://ascentialcdn.filespin.io/api/v1/conversion/1a22539ff6e94e288d6a3aa1a3a9ace5 | J2: F48khKZhKHM | L2: https://www.lovethework.com/work/entries/caption-with-intention-758922
A3: 2 | B3: Gold | C3: AirPods Pro 2 Hearing Aid Feature | D3: Apple | E3: AirPods Pro 2 | F3: Apple | G3: United States | H3: A04 - Product Design | I3: https://ascentialcdn.filespin.io/api/v1/conversion/d124f3704bf34fe8a63e19e8325d9220 | J3: OzScknoWq6U | L3: https://www.lovethework.com/work/entries/airpods-pro-2-hearing-aid-feature-748829
A4: 3 | B4: Gold | C4: Nigrum Corpus | D4: Idomed | E4: Nigrum Corpus | F4: Artplan | G4: Brazil | H4: A06 - Books | I4: https://ascentialcdn.filespin.io/api/v1/conversion/83e9fc2a93254c029a34755ff3c96853 | J4: RCK4iiCB2P0 | L4: https://www.lovethework.com/work/entries/nigrum-corpus-764511
A5: 4 | B5: Gold | C5: CarrefourSA - Ghost Town | D5: CarrefourSA | E5: Retail | F5: TBWA\Istanbul | G5: Turkey | H5: A08 - Brand Environment & Experience Design | I5: https://ascentialcdn.filespin.io/api/v1/conversion/a8b0865217084e348df3921cebc7c41f | J5: 0tKFbogECr4 | L5: https://www.lovethework.com/work/entries/carrefoursa-ghost-town-748805
A6: 5 | B6: Gold | C6: Spreadbeats | D6: Spotify | E6: Spotify | F6: FCB New York | G6: United States | H6: A09 - Design-Driven Effectiveness | I6: https://ascentialcdn.filespin.io/api/v1/conversion/4ebdb10e5b80456a925dc283ac7e501a | J6: Z_lbVlhO9HE | L6: https://www.lovethework.com/work/entries/spreadbeats-748953
A7: 6 | B7: Silver | C7: Spreadbeats | D7: Spotify | E7: Spotify | F7: FCB New York | G7: United States | H7: A07 - Digital Design | I7: https://ascentialcdn.filespin.io/api/v1/conversion/1cc1b629542a4d1db92e5b0d90116de7 | J7: Z_lbVlhO9HE | L7: https://www.lovethework.com/work/entries/spreadbeats-748925
A8: 7 | B8: Silver | C8: Price Packs | D8: Penny | E8: Food/Non-Food | F8: Serviceplan Germany | G8: Germany | H8: A09 - Design-Driven Effectiveness | I8: https://ascentialcdn.filespin.io/api/v1/conversion/67b6df2a0fe64deeb274c91d50040c54 | J8: cnAXR4lk6R0 | L8: https://www.lovethework.com/work/entries/price-packs-748846
A9: 8 | B9: Silver | C9: The Shakespeare BIC | D9: BIC | E9: BIC Crystal Pen | F9: VML | G9: Brazil | H9: A11 - Special Editions & Bespoke Items | I9: https://ascentialcdn.filespin.io/api/v1/conversion/352257f3d008491e95e0ccbdfe8a4469 | J9: 5ngNVTeyi4g | L9: https://www.lovethework.com/work/entries/the-shakespeare-bic-749146
A10: 9 | B10: Silver | C10: Sounds of the Land | D10: Billboard Arabia | E10: Billboard Arabia | F10: SRMG Labs | G10: Saudi Arabia | H10: A14 - Promotional Items/Promotional Printed Media | I10: https://ascentialcdn.filespin.io/api/v1/conversion/19a407ae77ab4664baed61135cc5ae9f | J10: gD1XqvQaMR0 | L10: https://www.lovethework.com/work/entries/sounds-of-the-land-758892
A11: 10 | B11: Silver | C11: Code My Crown | D11: Dove | E11: Dove | F11: Edelman | G11: United Kingdom | H11: B01 - Inclusive Design | I11: https://ascentialcdn.filespin.io/api/v1/conversion/dc773a5191b947ea85626af886046a69 | J11: stQ442QJ9pg | L11: https://www.lovethework.com/work/entries/code-my-crown-749303
A12: 11 | B12: Silver | C12: 1837 Tiffany Blue Conservation | D12: Tiffany & Co. | E12: Tiffany & Co. | F12: L&C | G12: United States | H12: B02 - Sustainability-Focused Design | I12: https://ascentialcdn.filespin.io/api/v1/conversion/a9e8fdb5892d441587b7c4c55eb3d5fb | J12: npGswWNcZC8 | L12: https://www.lovethework.com/work/entries/1837-tiffany-blue-conservation-749213
A13: 12 | B13: Silver | C13: Fixables | D13: Philips | E13: Philips Personal Care | F13: LePub | G13: Netherlands | H13: B02 - Sustainability-Focused Design | I13: https://ascentialcdn.filespin.io/api/v1/conversion/9e978f653c5c45cf903985a90708656d | J13: grgsxQjK0B4 | L13: https://www.lovethework.com/work/entries/fixables-761443
... A32: 31 | B32: Bronze | C32: Fixables | D32: Philips | E32: Philips Personal Care | F32: LePub | G32: Netherlands | H32: B05 - Design for Behavioural Change | I32: https://ascentialcdn.filespin.io/api/v1/conversion/9e978f653c5c45cf903985a90708656d | J32: grgsxQjK0B4 | L32: https://www.lovethework.com/work/entries/fixables-761474

Sheet Media
A1: # | B1: Tier | C1: Campaign | D1: Brand | E1: Product/Service | F1: Agency | G1: Country | H1: Subcategory | I1: Image URL | J1: YouTube ID | K1: Campaign Group | L1: Entry URL
A2: 1 | B2: Grand Prix | C2: Dove Real Beauty Redefined for the AI Era | D2: Dove | E2: Dove | F2: Mindshare | G2: United States | H2: E01 - Media Insights & Strategy | I2: https://ascentialcdn.filespin.io/api/v1/conversion/da693fd61fc74ddfbb3525f638cd77c6 | J2: 8vYoL8nga-A | L2: https://www.lovethework.com/work/entries/dove-real-beauty-redefined-for-the-ai-era-746537
A3: 2 | B3: Gold | C3: Can't Unsee It | D3: Heinz Ketchup & Mustard | E3: Kraft Heinz | F3: Rethink | G3: Canada | H3: A01 - Consumer Goods | I3: https://ascentialcdn.filespin.io/api/v1/conversion/3db7ec7e31b7459bafa082009489d40e | J3: itiHi3WYcSs | L3: https://www.lovethework.com/work/entries/cant-unsee-it-745091
A4: 3 | B4: Gold | C4: Vaseline Verified | D4: Unilever | E4: Vaseline | F4: Ogilvy | G4: Singapore | H4: A02 - Healthcare | I4: https://ascentialcdn.filespin.io/api/v1/conversion/faf0755b0d4e4594ad93cb75d6288e3d | J4: ApwxlBruV90 | L4: https://www.lovethework.com/work/entries/vaseline-verified-745075
A5: 4 | B5: Gold | C5: Redditor Edit | D5: Skoda | E5: Automotive | F5: PHD | G5: United Kingdom | H5: A03 - Automotive | I5: https://ascentialcdn.filespin.io/api/v1/conversion/fa18cc31eca84cf2a41f8d9f4a3e8e89 | J5: KmLMtKsmwqA | L5: https://www.lovethework.com/work/entries/redditor-edit-744990
A6: 5 | B6: Gold | C6: Coupon Rain | D6: Mercado Livre | E6: Mercado Livre | F6: GUT | G6: Brazil | H6: A04 - Travel, Leisure, Retail, Restaurants & Fast-Food Chains | I6: https://ascentialcdn.filespin.io/api/v1/conversion/5418c22c9d864f579ce966a3f138628e | J6: RXw_xdHILoU | L6: https://www.lovethework.com/work/entries/coupon-rain-745092
A7: 6 | B7: Gold | C7: The Final Exam | D7: Change the Ref | E7: Pro Bono | F7: Energy BBDO | G7: United States | H7: A07 - Not-for-Profit / Charity / Government | I7: https://ascentialcdn.filespin.io/api/v1/conversion/615e3a15eabf457d91d317468a12d825 | J7: Ljsstj4eiko | L7: https://www.lovethework.com/work/entries/the-final-exam-761015
A8: 7 | B8: Gold | C8: Streaming Bars | D8: Heineken | E8: Heineken | F8: LePub | G8: Brazil | H8: B01 - Use of Screens & Audio Visual Platforms | I8: https://ascentialcdn.filespin.io/api/v1/conversion/d0be42343a2e4aaea76238ca95dfcbab | J8: 0izbOb7N73g | L8: https://www.lovethework.com/work/entries/streaming-bars-745041
A9: 8 | B9: Gold | C9: "Raise Your Banners" | D9: HBO | E9: House of the Dragon Season 2 | F9: Giant Spoon | G9: United States | H9: B06 - Large-Scale Media | I9: https://ascentialcdn.filespin.io/api/v1/conversion/8568fb79e86c4ae994a024b682498651 | J9: S-r_T-LZBR0 | L9: https://www.lovethework.com/work/entries/raise-your-banners-745396
A10: 9 | B10: Gold | C10: Retro Influencers | D10: Skol | E10: Skol | F10: GUT | G10: Brazil | H10: B10 - Use of Social Platforms | I10: https://ascentialcdn.filespin.io/api/v1/conversion/8d30857fd8bf46f3ab1b9c9b3d0a50fa | J10: FKLnmbWukt0 | L10: https://www.lovethework.com/work/entries/retro-influencers-745595
A11: 10 | B11: Gold | C11: The Rewards Bag | D11: Tata | E11: Tata | F11: VML | G11: Uruguay | H11: B13 - Retail Media | I11: https://ascentialcdn.filespin.io/api/v1/conversion/9d355715dd4d4857a2f82df5c502290b | J11: RzJQ1TVItHI | L11: https://www.lovethework.com/work/entries/the-rewards-bag-745869
A12: 11 | B12: Gold | C12: Fictional Insurance | D12: RCN/Prime | E12: Insurance | F12: DDB Colombia | G12: Colombia | H12: C02 - Use of Brand or Product Integration into a Programme or Platform | I12: https://ascentialcdn.filespin.io/api/v1/conversion/9f879201572d4cb9aa1e14e89b6a4f2f | J12: OctiVcwaiXI | L12: https://www.lovethework.com/work/entries/fictional-insurance-745946
A13: 12 | B13: Gold | C13: First Ever Live Commercial Crossover | D13: Rocket | E13: Rocket | F13: Zenith | G13: United States | H13: E03 - Media Execution | I13: https://ascentialcdn.filespin.io/api/v1/conversion/c8c6d973823e408c926f4de68327d5df | J13: oF6A79XVZsc | L13: https://www.lovethework.com/work/entries/first-ever-live-commercial-crossover-759386
... A67: 66 | B67: Bronze | C67: Timeout Against Hate | D67: Foundation to Combat Antisemitism | E67: Foundation to Combat Antisemitism | F67: Mindshare | G67: United States | H67: E02 - Media Planning | I67: https://ascentialcdn.filespin.io/api/v1/conversion/e43c43ae03f240ed8fbaf95002d5d795 | J67: vimeo:1083894799 | L67: https://www.lovethework.com/work/entries/timeout-against-hate-746540

Sheet Film Craft
A1: # | B1: Tier | C1: Campaign | D1: Brand | E1: Product/Service | F1: Agency | G1: Country | H1: Subcategory | I1: Image URL | J1: YouTube ID | K1: Campaign Group | L1: Entry URL
A2: 1 | B2: Grand Prix | C2: TELSTRA - BETTER ON A BETTER NETWORK | D2: TELSTRA | E2: TELSTRA | F2: BEAR MEETS EAGLE ON FIRE | G2: Australia | H2: Animation | I2: digital-presentation-images/film-craft-telstra-telstra-better-on-a-better-network.webp | J2: L8wOtakkr28 | K2: telstra-better-on-a-better-network | L2: https://www.lovethework.com/work/entries/telstra-better-on-a-better-network-765315
A3: 2 | B3: Gold | C3: TELSTRA - BETTER ON A BETTER NETWORK | D3: TELSTRA | E3: TELSTRA | F3: BEAR MEETS EAGLE ON FIRE | G3: Australia | H3: Production Design/Art Direction | I3: digital-presentation-images/film-craft-telstra-telstra-better-on-a-better-network.webp | J3: L8wOtakkr28 | K3: telstra-better-on-a-better-network | L3: https://www.lovethework.com/work/entries/telstra-better-on-a-better-network-765311
A4: 3 | B4: Gold | C4: CONSIDERING WHAT? | D4: CHANNEL 4 | E4: PARALYMPICS 2024 | F4: WORK EDITORIAL | G4: United Kingdom | H4: Editing | I4: https://ascentialcdn.filespin.io/api/v1/storyboard/10fba32c76a941749debf9069e930560/storyboard_000008.jpg | J4: bUs_mNTNwvE | L4: https://www.lovethework.com/work/entries/considering-what-765324
A5: 4 | B5: Gold | C5: GUAO GUAO | D5: DESPERADOS | E5: DESPERADOS | F5: LEPUB | G5: Italy | H5: Casting | I5: digital-presentation-images/film-craft-desperados-guao-guao.webp | J5: N58e8-bziA0 | L5: https://www.lovethework.com/work/entries/guao-guao-765356
A6: 5 | B6: Gold | C6: FIND YOUR FRIENDS | D6: APPLE | E6: PRECISION FINDING | F6: APPLE | G6: United States | H6: Use of Licensed/Adapted Music | I6: digital-presentation-images/film-craft-apple-find-your-friends.webp | J6: LO4wamMlCKQ | L6: https://www.lovethework.com/work/entries/find-your-friends-765322
A7: 6 | B7: Gold | C7: PARIS PARALYMPICS 2024: CONSIDERING WHAT? | D7: CHANNEL 4 | E7: CHANNEL 4 | F7: BISCUIT FILMWORKS | G7: United Kingdom | H7: Direction | I7: https://ascentialcdn.filespin.io/api/v1/storyboard/70b14ba69a8a40b7b9b991d15ac41e79/storyboard_000008.jpg | J7: 2np3KfLrA_M | L7: https://www.lovethework.com/work/entries/paris-paralympics-2024-considering-what-765981
A8: 7 | B8: Gold | C8: A TALE AS OLD AS WEBSITES | D8: SQUARESPACE | E8: SQUARESPACE | F8: SQUARESPACE | G8: United States | H8: Direction | I8: digital-presentation-images/film-craft-squarespace-a-tale-as-old-as-websites.webp | J8: LXQtg237SKY | L8: https://www.lovethework.com/work/entries/a-tale-as-old-as-websites-765346
A9: 8 | B9: Gold | C9: DONKEY | D9: TELSTRA | E9: TELSTRA | F9: REVOLVER | G9: Australia | H9: Direction | I9: digital-presentation-images/film-craft-telstra-donkey.webp | J9: vimeo:1028285893 | K9: telstra-donkey | L9: https://www.lovethework.com/work/entries/donkey-765344
A10: 9 | B10: Gold | C10: A$AP ROCKY - TAILOR SWIF | D10: A$AP ROCKY | E10: A$AP ROCKY | F10: ICONOCLAST | G10: United States | H10: Direction | I10: https://ascentialcdn.filespin.io/api/v1/storyboard/7819511744634f7a81824e1b2a278ae1/storyboard_000008.jpg | J10: 5URefVYaJrA | L10: https://www.lovethework.com/work/entries/aap-rocky-tailor-swif-765317
A11: 10 | B11: Gold | C11: RENAULT - ARGENTINA | D11: RENAULT | E11: RENAULT E-TECH | F11: PUBLICIS CONSEIL | G11: France | H11: Cinematography | I11: digital-presentation-images/film-craft-renault-renault-argentina.webp | J11: IQovoot_ZUM | L11: https://www.lovethework.com/work/entries/renault-argentina-766426
A12: 11 | B12: Silver | C12: GUAO GUAO | D12: DESPERADOS | E12: DESPERADOS | F12: LEPUB | G12: Italy | H12: Use of Original Music | I12: digital-presentation-images/film-craft-desperados-guao-guao.webp | J12: N58e8-bziA0 | L12: https://www.lovethework.com/work/entries/guao-guao-765357
A13: 12 | B13: Silver | C13: MOMENTS | D13: VOLVO | E13: VOLVO EX90 | F13: STENDAHLS | G13: Sweden | H13: Editing | I13: https://ascentialcdn.filespin.io/api/v1/storyboard/346a403fc27b4b2db49c84361f4c8081/storyboard_000008.jpg | J13: cQX-QXxwGvA | L13: https://www.lovethework.com/work/entries/moments-765347
A14: 13 | B14: Silver | C14: NIKE "SUNSHINE" | D14: NIKE | F14: TRAFIK | H14: Colour Correction/Grading | I14: https://ascentialcdn.filespin.io/api/v1/storyboard/b9ed0aae1ae84082882cb4a1ec460780/storyboard_000008.jpg | J14: FFFmnfdBrm8 | L14: https://www.lovethework.com/work/entries/nike-sunshine-765328
A15: 14 | B15: Silver | C15: A TALE AS OLD AS WEBSITES | D15: SQUARESPACE | E15: SQUARESPACE | F15: SQUARESPACE | G15: United States | H15: Casting | I15: digital-presentation-images/film-craft-squarespace-a-tale-as-old-as-websites.webp | J15: LXQtg237SKY | L15: https://www.lovethework.com/work/entries/a-tale-as-old-as-websites-765331
A16: 15 | B16: Silver | C16: FLOCK | D16: APPLE | E16: IPHONE | F16: TBWA\MEDIA ARTS LAB | G16: United States | H16: Animation | I16: digital-presentation-images/film-craft-apple-flock.webp | J16: jom8zBix-4c | K16: apple-flock | L16: https://www.lovethework.com/work/entries/flock-765354
A17: 16 | B17: Silver | C17: MOMENTS | D17: VOLVO | E17: VOLVO EX90 | F17: STENDAHLS | G17: Sweden | H17: Cinematography | I17: https://ascentialcdn.filespin.io/api/v1/storyboard/346a403fc27b4b2db49c84361f4c8081/storyboard_000008.jpg | J17: cQX-QXxwGvA | L17: https://www.lovethework.com/work/entries/moments-765347
A18: 17 | B18: Silver | C18: IN HOT WATER | D18: WORLD WILDLIFE FUND (WWF) | E18: WWF | F18: NOMINT | G18: United Kingdom | H18: Animation | I18: digital-presentation-images/film-craft-world-wildlife-fund-wwf-in-hot-water.webp | J18: vimeo:1028875237 | L18: https://www.lovethework.com/work/entries/in-hot-water-765332
A19: 18 | B19: Silver | C19: DONKEY | D19: TELSTRA | E19: TELSTRA | F19: REVOLVER | G19: Australia | H19: Production Design/Art Direction | I19: digital-presentation-images/film-craft-telstra-donkey.webp | J19: vimeo:1028285893 | K19: telstra-donkey | L19: https://www.lovethework.com/work/entries/donkey-765336
A20: 19 | B20: Silver | C20: COFFIN | D20: LIFE360 | E20: LIFE360 | F20: ALTO | G20: United States | H20: Direction | I20: https://ascentialcdn.filespin.io/api/v1/storyboard/3cd320dd9fcd4445a86f756e25d0402e/storyboard_000008.jpg | J20: hlqerWZSCpE | L20: https://www.lovethework.com/work/entries/coffin-765342
A21: 20 | B21: Silver | C21: RENAULT - ARGENTINA | D21: RENAULT | E21: RENAULT E-TECH | F21: PUBLICIS CONSEIL | G21: France | H21: Production Design/Art Direction | I21: digital-presentation-images/film-craft-renault-renault-argentina.webp | J21: IQovoot_ZUM | L21: https://www.lovethework.com/work/entries/renault-argentina-765345
A22: 21 | B22: Silver | C22: A$AP ROCKY - TAILOR SWIF | D22: A$AP ROCKY | E22: A$AP ROCKY | F22: ICONOCLAST | G22: United States | H22: Production Design/Art Direction | I22: https://ascentialcdn.filespin.io/api/v1/storyboard/7819511744634f7a81824e1b2a278ae1/storyboard_000008.jpg | J22: 5URefVYaJrA | L22: https://www.lovethework.com/work/entries/aap-rocky-tailor-swif-765343
A23: 22 | B23: Silver | C23: BELIEVE IN CHICKEN | D23: KFC | E23: FOOD (FRIED CHICKEN) | F23: MOTHER | G23: United Kingdom | H23: Use of Original Music | I23: digital-presentation-images/film-craft-kfc-believe-in-chicken.webp | J23: Pb4SnxpJLyE | L23: https://www.lovethework.com/work/entries/believe-in-chicken-765320
A24: 23 | B24: Bronze | C24: FLOCK | D24: APPLE | E24: IPHONE | F24: TBWA\MEDIA ARTS LAB | G24: United States | H24: Editing | I24: digital-presentation-images/film-craft-apple-flock.webp | J24: jom8zBix-4c | K24: apple-flock | L24: https://www.lovethework.com/work/entries/flock-765363
A25: 24 | B25: Bronze | C25: EVERYTHING OR NOTHING | D25: RIYADH SEASON | E25: BOXING FIGHT | F25: BIGTIME CREATIVE SHOP | G25: Saudi Arabia | H25: Production Design/Art Direction | I25: https://ascentialcdn.filespin.io/api/v1/storyboard/99b51143eb5a45779617eee2310c73e0/storyboard_000008.jpg | J25: vimeo:987240751 | L25: https://www.lovethework.com/work/entries/everything-or-nothing-765340
A26: 25 | B26: Bronze | C26: NEVER JUST A PERIOD | D26: BODYFORM | E26: BODYFORM | F26: AMV BBDO | G26: United Kingdom | H26: Direction | I26: digital-presentation-images/film-craft-bodyform-never-just-a-period.webp | J26: EQW59KR3c4U | L26: https://www.lovethework.com/work/entries/never-just-a-period-765319
A27: 26 | B27: Bronze | C27: 18 MONTHS | D27: SECOND NURTURE | E27: CHARITY | F27: KLICK HEALTH | G27: Canada | H27: Animation | I27: digital-presentation-images/film-craft-second-nurture-18-months.webp | J27: vimeo:1092249009 | L27: https://www.lovethework.com/work/entries/18-months-765335
A28: 27 | B28: Bronze | C28: THE SHOOTING | D28: LA UNIÓN NEWSPAPER / ARTICULO 19 | E28: LA UNIÃN NEWSPAPER / ARTICULO 19 | F28: GREY | G28: Mexico | H28: Direction | I28: digital-presentation-images/film-craft-la-union-newspaper-the-shooting.webp | J28: -saAXmItj_U | L28: https://www.lovethework.com/work/entries/the-shooting-765350
A29: 28 | B29: Bronze | C29: A TALE AS OLD AS WEBSITES | D29: SQUARESPACE | E29: SQUARESPACE | F29: SQUARESPACE | G29: United States | H29: Production Design/Art Direction | I29: digital-presentation-images/film-craft-squarespace-a-tale-as-old-as-websites.webp | J29: LXQtg237SKY | L29: https://www.lovethework.com/work/entries/a-tale-as-old-as-websites-765338
A30: 29 | B30: Bronze | C30: WITH LOVE, ITALY | D30: NESTLE | E30: SANPELLEGRINO CIAO! | F30: OGILVY | G30: United States | H30: Script | I30: digital-presentation-images/film-craft-nestle-with-love-italy.webp | J30: k0CfyHTmb4Q | L30: https://www.lovethework.com/work/entries/with-love-italy-765329
A31: 30 | B31: Bronze | C31: OBSESSION | D31: RIYADH SEASON | E31: BOXING FIGHT | F31: BIGTIME CREATIVE SHOP | G31: Saudi Arabia | H31: Visual Effects | I31: digital-presentation-images/film-craft-riyadh-season-obsession.webp | J31: PdcUQwAtDDs | L31: https://www.lovethework.com/work/entries/obsession-765355
A32: 31 | B32: Bronze | C32: SUBMERGED | D32: APPLE | E32: VISION PRO | F32: APPLE | G32: United States | H32: Achievement in Production | I32: digital-presentation-images/film-craft-apple-submerged.webp | J32: lP8LLIjCe6Q | L32: https://www.lovethework.com/work/entries/submerged-765360
A33: 32 | B33: Bronze | C33: KFC: BELIEVE IN CHICKEN | D33: KFC | E33: FOOD (FRIED CHICKEN) | F33: LUX ARTISTS | G33: United Kingdom | H33: Cinematography | I33: digital-presentation-images/film-craft-kfc-believe-in-chicken.webp | J33: Pb4SnxpJLyE | L33: https://www.lovethework.com/work/entries/kfc-believe-in-chicken-765358
A34: 33 | B34: Bronze | C34: NAME THE BIAS | D34: PEOPLE LIKE US | E34: PEOPLE LIKE US | F34: NEW LAND | G34: Denmark | H34: Cinematography | I34: https://ascentialcdn.filespin.io/api/v1/storyboard/78d81508b5494a40bba8366f2f62eed1/storyboard_000008.jpg | J34: 3uTwt6FYX98 | L34: https://www.lovethework.com/work/entries/name-the-bias-765351
A35: 34 | B35: Bronze | C35: FIGHT FOR THAIS' GUT | D35: DUTCHIE | E35: DUTCHIE | F35: OGILVY | G35: Thailand | H35: Casting | I35: digital-presentation-images/film-craft-dutchie-fight-for-thais-gut.webp | J35: vimeo:1152947690 | L35: https://www.lovethework.com/work/entries/fight-for-thais-gut-765333
A36: 35 | B36: Bronze | C36: WHEN YOU'VE DONE ENOUGH - EVIL'D ENOUGH | D36: UBER EATS | E36: FOOD DELIVERY SERVICE | F36: MOTHER | G36: United Kingdom | H36: Casting | I36: https://ascentialcdn.filespin.io/api/v1/storyboard/9e327b1cbb6d4295ae6a602857eb395c/storyboard_000008.jpg | J36: W3q1PQGXaps | L36: https://www.lovethework.com/work/entries/when-youve-done-enough-evild-enough-765334
... A50: 49 | B50: Bronze | C50: WALRUS WHIZZER | D50: VIRGIN | E50: VIRGIN MEDIA | F50: UNTOLD STUDIOS | G50: United Kingdom | H50: Visual Effects | I50: https://ascentialcdn.filespin.io/api/v1/storyboard/a7d2b86e8d154d35bb56d32c7d6f43ca/storyboard_000008.jpg | J50: VJ2TZs9WJng | L50: https://www.lovethework.com/work/entries/walrus-whizzer-765353

Sheet Summary
A1: Audio & Radio — Cannes Lions 2025
A3: Tier | B3: Count
A4: Grand Prix | B4: =COUNTIF('Audio & Radio'!B:B,"Grand Prix")
A5: Gold | B5: =COUNTIF('Audio & Radio'!B:B,"Gold")
A6: Silver | B6: =COUNTIF('Audio & Radio'!B:B,"Silver")
A7: Bronze | B7: =COUNTIF('Audio & Radio'!B:B,"Bronze")
A8: Total | B8: =SUM(B4:B7)
A10: Brand Experience & Activation — Cannes Lions 2025
A12: Tier | B12: Count
A13: Grand Prix | B13: =COUNTIF('Brand Experience & Activation'!B:B,"Grand Prix")
A14: Gold | B14: =COUNTIF('Brand Experience & Activation'!B:B,"Gold")
A15: Silver | B15: =COUNTIF('Brand Experience & Activation'!B:B,"Silver")
A16: Bronze | B16: =COUNTIF('Brand Experience & Activation'!B:B,"Bronze")
A17: Total | B17: =SUM(B13:B16)
A19: Design — Cannes Lions 2025
A21: Tier | B21: Count
A22: Grand Prix | B22: =COUNTIF('Design'!B:B,"Grand Prix")
A23: Gold | B23: =COUNTIF('Design'!B:B,"Gold")
A24: Silver | B24: =COUNTIF('Design'!B:B,"Silver")
A25: Bronze | B25: =COUNTIF('Design'!B:B,"Bronze")
A26: Total | B26: =SUM(B22:B25)
A28: Film — Cannes Lions 2025
A30: Tier | B30: Count
A31: Grand Prix | B31: =COUNTIF('Film'!B:B,"Grand Prix")
A32: Gold | B32: =COUNTIF('Film'!B:B,"Gold")
A33: Silver | B33: =COUNTIF('Film'!B:B,"Silver")
A34: Bronze | B34: =COUNTIF('Film'!B:B,"Bronze")
A35: Total | B35: =SUM(B31:B34)
A37: Film Craft — Cannes Lions 2025
A39: Tier | B39: Count
A40: Grand Prix | B40: =COUNTIF('Film Craft'!B:B,"Grand Prix")
A41: Gold | B41: =COUNTIF('Film Craft'!B:B,"Gold")
A42: Silver | B42: =COUNTIF('Film Craft'!B:B,"Silver")
A43: Bronze | B43: =COUNTIF('Film Craft'!B:B,"Bronze")
A44: Total | B44: =SUM(B40:B43)
A46: Media — Cannes Lions 2025
A48: Tier | B48: Count
A49: Grand Prix | B49: =COUNTIF('Media'!B:B,"Grand Prix")
A50: Gold | B50: =COUNTIF('Media'!B:B,"Gold")
A51: Silver | B51: =COUNTIF('Media'!B:B,"Silver")
...

Sheet Grand Prix for Good
A1: # | B1: Tier | C1: Campaign | D1: Brand | E1: Product/Service | F1: Agency | G1: Country | H1: Subcategory | I1: Image URL | J1: YouTube ID | K1: Campaign Group | L1: Entry URL
A2: 1 | B2: Grand Prix | C2: THE BEST PLACE IN THE WORLD TO HAVE HERPES | D2: NEW ZEALAND HERPES FOUNDATION | E2: NEW ZEALAND HERPES FOUNDATION | F2: FINCH | G2: Australia | H2: Grand Prix for Good | I2: digital-presentation-images/grand-prix-for-good-new-zealand-herpes-foundation-the-best-place-in-the-world-to-have-herpes.webp | J2: vimeo:1083074994 | L2: https://www.lovethework.com/work/entries/the-best-place-in-the-world-to-have-herpes-767497

Sheet Glass - The Lion for Change
A1: # | B1: Tier | C1: Campaign | D1: Brand | E1: Product/Service | F1: Agency | G1: Country | H1: Subcategory | I1: Image URL | J1: YouTube ID | K1: Campaign Group | L1: Entry URL
A2: 1 | B2: Grand Prix | C2: REAL BEAUTY: HOW A SOAP BRAND CREATED A GLOBAL SELF-ESTEEM MOVEMENT | D2: DOVE | E2: DOVE | F2: OGILVY UK | G2: United Kingdom | H2: Long-Term Brand Platform | I2: https://ascentialcdn.filespin.io/api/v1/conversion/f68a5a2f3d844f2b9e241462ec640c44 | J2: puQ0PNZ1W-A | L2: https://www.lovethework.com/work/entries/real-beauty-how-a-soap-brand-created-a-global-self-esteem-movement-754479
A3: 2 | B3: Gold | C3: HERALBONY | D3: HERALBONY, HERALBONY CO. | E3: HERALBONY | F3: LTD. | G3: Japan | H3: Product/Service | I3: https://ascentialcdn.filespin.io/api/v1/conversion/88e24a7cf24b40a590af455059ceeaf9 | J3: vimeo:1093399082 | L3: https://www.lovethework.com/work/entries/heralbony-754170
A4: 3 | B4: Silver | C4: THE PEN TO RIGHT HISTORY | D4: LAST PRISONER PROJECT | E4: NON-FOR-PROFIT | F4: McCANN | G4: United States | H4: Initiatives | I4: https://ascentialcdn.filespin.io/api/v1/conversion/5c13816c86fa4023933a56ac6d5c3593 | J4: SDME83-pHnQ | L4: https://www.lovethework.com/work/entries/the-pen-to-right-history-762088
A5: 4 | B5: Silver | C5: AXA - THREE WORDS | D5: AXA | E5: INSURANCE | F5: PUBLICIS CONSEIL | G5: France | H5: Product/Service | I5: https://ascentialcdn.filespin.io/api/v1/conversion/e1a85ff134e545c7b049791151432028 | J5: pY-03zuV7mE | L5: https://www.lovethework.com/work/entries/axa-three-words-754295
A6: 5 | B6: Bronze | C6: DOVE LOVE YOUR HAIR | D6: UNILEVER | E6: DOVE HAIR CARE | F6: EDELMAN | G6: United States | H6: Long-Term Brand Platform | I6: https://ascentialcdn.filespin.io/api/v1/conversion/bb0973df9f0d4e1e83e3c9ef7dc4d714 | J6: vimeo:1093399067 | L6: https://www.lovethework.com/work/entries/dove-love-your-hair-760237
A7: 6 | B7: Bronze | C7: LIVEFEARLESS | D7: BODYFORM | E7: BODYFORM | F7: AMV BBDO | G7: United Kingdom | H7: Long-Term Brand Platform | I7: https://ascentialcdn.filespin.io/api/v1/conversion/fdf9d053919448b2bf6bc7e2604789c5 | J7: vimeo:1093400188 | L7: https://www.lovethework.com/work/entries/livefearless-754488
A8: 7 | B8: Bronze | C8: HER DOME | D8: GOVERNMENT OF THE STATE OF SAO PAULO | E8: GOVERNMENT OF THE STATE OF SÃO PAULO - WOMEN'S SAFETY | F8: DPZ | G8: Brazil | H8: Technology | I8: https://ascentialcdn.filespin.io/api/v1/conversion/785860d791fe410495aecad052809d64 | J8: vimeo:1093399045 | L8: https://www.lovethework.com/work/entries/her-dome-754187
A9: 8 | B9: Bronze | C9: GRAD IN BLACK | D9: VULT | E9: HAIR PRODUCT LINE | F9: GUT | G9: Brazil | H9: Product/Service | I9: https://ascentialcdn.filespin.io/api/v1/conversion/2488030bdfa840c99e3568fe7b1001d2 | J9: vimeo:1033200856 | L9: https://www.lovethework.com/work/entries/grad-in-black-762134

Sheet Creative Bus. Transformation
A1: # | B1: Tier | C1: Campaign | D1: Brand | E1: Product/Service | F1: Agency | G1: Country | H1: Subcategory | I1: Image URL | J1: YouTube ID | K1: Campaign Group | L1: Entry URL
A2: 1 | B2: Grand Prix | C2: AXA - THREE WORDS | D2: AXA | E2: INSURANCE | F2: PUBLICIS CONSEIL | G2: France | H2: Transformative Strategy | I2: digital-presentation-images/creative-business-transformation-axa-axa-three-words.webp | J2: pY-03zuV7mE | L2: https://www.lovethework.com/work/entries/axa-three-words-757718
A3: 2 | B3: Gold | C3: LUCKY YATRA | D3: INDIAN RAILWAYS | E3: RAILWAY SERVICE | F3: FCB INDIA | G3: India | H3: Targeting, Insights & Personalisation | I3: digital-presentation-images/creative-business-transformation-indian-railways-lucky-yatra.webp | J3: 19fzAvuFq0I | L3: https://www.lovethework.com/work/entries/lucky-yatra-757794
A4: 3 | B4: Silver | C4: BUILDING A MORE RESILIENT AUSTRALIA | D4: SUNCORP | E4: INSURANCE | F4: LEO | G4: Australia | H4: Long-Term Brand Platform | I4: digital-presentation-images/creative-business-transformation-suncorp-building-a-more-resilient-australia.webp | J4: vimeo:1094885092 | L4: https://www.lovethework.com/work/entries/building-a-more-resilient-australia-757856
A5: 4 | B5: Silver | C5: RENAULT - LONG-TERM | D5: RENAULT | E5: AUTOMOTIVE | F5: PUBLICIS CONSEIL | G5: France | H5: Long-Term Brand Platform | I5: https://ascentialcdn.filespin.io/api/v1/storyboard/f4d05b0940354e91afbb9acbfc09d056/storyboard_000008.jpg | J5: GYWg2HktW-0 | L5: https://www.lovethework.com/work/entries/renault-long-term-757900
A6: 5 | B6: Bronze | C6: RECIPE FOR GROWTH | D6: IFOOD | E6: IFOOD B2B | F6: DM9 | G6: Brazil | H6: Transformative Strategy | I6: digital-presentation-images/creative-business-transformation-ifood-recipe-for-growth.webp | J6: vimeo:1080197730 | L6: https://www.lovethework.com/work/entries/recipe-for-growth-757609
A7: 6 | B7: Bronze | C7: IT'S A CHEETOS THING | D7: CHEETOS | PEPSICO | E7: CHEETOS | F7: GOODBY SILVERSTEIN & PARTNERS | G7: United States | H7: Long-Term Brand Platform | I7: digital-presentation-images/creative-business-transformation-cheetos-pepsico-its-a-cheetos-thing.webp | J7: vimeo:1094791063 | L7: https://www.lovethework.com/work/entries/its-a-cheetos-thing-765189
A8: 7 | B8: Bronze | C8: BACKING THE BARS | D8: HEINEKEN | E8: HEINEKEN | F8: LEPUB | G8: Italy | H8: Long-Term Brand Platform | I8: https://ascentialcdn.filespin.io/api/v1/conversion/9d89a2d0441e4f1498beb7e41712ebbf | J8: r2mR8LV53PE | L8: https://www.lovethework.com/work/entries/backing-the-bars-762510

Sheet Luxury
A1: # | B1: Tier | C1: Campaign | D1: Brand | E1: Product/Service | F1: Agency | G1: Country | H1: Subcategory | I1: Image URL | J1: YouTube ID | K1: Campaign Group | L1: Entry URL
A2: 1 | B2: Grand Prix | C2: THE PARTNERSHIP THAT CHANGED EVERYTHING | D2: LVMH | E2: LVMH | F2: HAVAS PLAY | G2: France | H2: Partnerships/Collaborations | I2: https://ascentialcdn.filespin.io/api/v1/conversion/618cd520f9a24294b091f0641b1abd65 | J2: vpsibWyRnKw | L2: https://www.lovethework.com/work/entries/the-partnership-that-changed-everything-758515
A3: 2 | B3: Gold | C3: LATE CHECKOUT: A RITZ-CARLTON STORY | D3: THE RITZ-CARLTON, LATE CHECKOUT | E3: LATE CHECKOUT COLLECTION, RITZ-CARLTON HOTELS | F3: LITTLE SPAIN | G3: Spain | H3: Brand Storytelling | I3: https://ascentialcdn.filespin.io/api/v1/conversion/ba8c7874143548279ee2ef8936cfee6d | J3: vimeo:1094659374 | L3: https://www.lovethework.com/work/entries/late-checkout-a-ritz-carlton-story-758432
A4: 3 | B4: Silver | C4: 1837 TIFFANY BLUE CONSERVATION | D4: TIFFANY & CO. | E4: TIFFANY & CO. | F4: L&C | G4: United States | H4: Sustainable Luxury | I4: https://ascentialcdn.filespin.io/api/v1/conversion/a9e8fdb5892d441587b7c4c55eb3d5fb | J4: _JhBOf0OJrQ | L4: https://www.lovethework.com/work/entries/1837-tiffany-blue-conservation-758489
A5: 4 | B5: Bronze | C5: DON'T CALL IT LOVE | D5: YVES SAINT LAURENT BEAUTE | E5: ABUSE IS NOT LOVE | F5: BETC | G5: France | H5: Social Campaign | I5: https://ascentialcdn.filespin.io/api/v1/conversion/b28805c7458d487cbf93d349fcf83dd2 | J5: eBnKDL57i7Y | L5: https://www.lovethework.com/work/entries/dont-call-it-love-762992
A6: 5 | B6: Bronze | C6: PRADA: BEYOND THE LINE | D6: PRADA BEAUTÉ | E6: PRADA LUNA ROSSA OCEAN | F6: McCANN | G6: France | H6: Brand Storytelling | I6: https://ascentialcdn.filespin.io/api/v1/conversion/d6d662c2af9b477e9d70359dc900be0f | J6: rXF9wl0BCWE | L6: https://www.lovethework.com/work/entries/prada-beyond-the-line-758381
A7: 6 | B7: Bronze | C7: THE EVERLASTING LOGO | D7: BOTTEGA VENETA | E7: BOTTEGA VENETA | F7: LEPUB | G7: Italy | H7: Experience | I7: https://ascentialcdn.filespin.io/api/v1/conversion/f0ac97dd3a4547da87ada6ad61058cc1 | J7: ZzT1nS6DJqc | L7: https://www.lovethework.com/work/entries/the-everlasting-logo-758398
A8: 7 | B8: Bronze | C8: LOEWE TIKTOK | D8: LOEWE | E8: LOEWE | F8: LOEWE | G8: Spain | H8: Social Campaign | I8: https://ascentialcdn.filespin.io/api/v1/conversion/d2cfdb97c2fc40fd9ab74040e3daa0a2 | J8: vimeo:1094660435 | L8: https://www.lovethework.com/work/entries/loewe-tiktok-762978

Sheet Innovation
A1: # | B1: Tier | C1: Campaign | D1: Brand | E1: Product/Service | F1: Agency | G1: Country | H1: Subcategory | I1: Image URL | J1: YouTube ID | K1: Campaign Group | L1: Entry URL
A2: 1 | B2: Grand Prix | C2: SOUNDS RIGHT | D2: MUSEUM FOR THE UNITED NATIONS - UN LIVE, SPOTIFY | E2: MUSIC | F2: AKQA | G2: Denmark | H2: Environmental Innovation | I2: https://ascentialcdn.filespin.io/api/v1/conversion/5015b68d24bd481a8fcfefc326f5b154 | J2: vimeo:1094746280 | L2: https://www.lovethework.com/work/entries/sounds-right-761761
