Workbook

Sheet Summary
A1: BRAIN CANNESDY — WINNERS DATABASE
A2: Awards summary · auto-generated by scripts/rebuild_summary.py · 2026-06-26
A4: TOTALS BY YEAR
A5: Year | B5: Grand Prix | C5: Gold | D5: Silver | E5: Bronze | F5: Titanium | G5: Total
A6: 2025 | B6: 34 | C6: 148 | D6: 278 | E6: 414 | F6: 4 | G6: 878
A7: 2026 | B7: 25 | C7: 91 | D7: 171 | E7: 272 | F7: 0 | G7: 559
A8: All years | B8: 59 | C8: 239 | D8: 449 | E8: 686 | F8: 4 | G8: 1437
A10: BY CATEGORY (all years)
A11: Category | B11: Grand Prix | C11: Gold | D11: Silver | E11: Bronze | F11: Titanium | G11: Total
A12: Creative Brand | B12: =COUNTIF('Creative Brand'!$B:$B,"Grand Prix") | C12: =COUNTIF('Creative Brand'!$B:$B,"Gold") | D12: =COUNTIF('Creative Brand'!$B:$B,"Silver") | E12: =COUNTIF('Creative Brand'!$B:$B,"Bronze") | F12: =COUNTIF('Creative Brand'!$B:$B,"Titanium Grand Prix")+COUNTIF('Creative Brand'!$B:$B,"Titanium") | G12: =SUM(B12:F12)
A13: Audio & Radio | B13: =COUNTIF('Audio & Radio'!$B:$B,"Grand Prix") | C13: =COUNTIF('Audio & Radio'!$B:$B,"Gold") | D13: =COUNTIF('Audio & Radio'!$B:$B,"Silver") | E13: =COUNTIF('Audio & Radio'!$B:$B,"Bronze") | F13: =COUNTIF('Audio & Radio'!$B:$B,"Titanium Grand Prix")+COUNTIF('Audio & Radio'!$B:$B,"Titanium") | G13: =SUM(B13:F13)
A14: Film | B14: =COUNTIF('Film'!$B:$B,"Grand Prix") | C14: =COUNTIF('Film'!$B:$B,"Gold") | D14: =COUNTIF('Film'!$B:$B,"Silver") | E14: =COUNTIF('Film'!$B:$B,"Bronze") | F14: =COUNTIF('Film'!$B:$B,"Titanium Grand Prix")+COUNTIF('Film'!$B:$B,"Titanium") | G14: =SUM(B14:F14)
A15: Outdoor | B15: =COUNTIF('Outdoor'!$B:$B,"Grand Prix") | C15: =COUNTIF('Outdoor'!$B:$B,"Gold") | D15: =COUNTIF('Outdoor'!$B:$B,"Silver") | E15: =COUNTIF('Outdoor'!$B:$B,"Bronze") | F15: =COUNTIF('Outdoor'!$B:$B,"Titanium Grand Prix")+COUNTIF('Outdoor'!$B:$B,"Titanium") | G15: =SUM(B15:F15)
A16: Print & Publishing | B16: =COUNTIF('Print & Publishing'!$B:$B,"Grand Prix") | C16: =COUNTIF('Print & Publishing'!$B:$B,"Gold") | D16: =COUNTIF('Print & Publishing'!$B:$B,"Silver") | E16: =COUNTIF('Print & Publishing'!$B:$B,"Bronze") | F16: =COUNTIF('Print & Publishing'!$B:$B,"Titanium Grand Prix")+COUNTIF('Print & Publishing'!$B:$B,"Titanium") | G16: =SUM(B16:F16)
A17: Design | B17: =COUNTIF('Design'!$B:$B,"Grand Prix") | C17: =COUNTIF('Design'!$B:$B,"Gold") | D17: =COUNTIF('Design'!$B:$B,"Silver") | E17: =COUNTIF('Design'!$B:$B,"Bronze") | F17: =COUNTIF('Design'!$B:$B,"Titanium Grand Prix")+COUNTIF('Design'!$B:$B,"Titanium") | G17: =SUM(B17:F17)
A18: Digital Craft | B18: =COUNTIF('Digital Craft'!$B:$B,"Grand Prix") | C18: =COUNTIF('Digital Craft'!$B:$B,"Gold") | D18: =COUNTIF('Digital Craft'!$B:$B,"Silver") | E18: =COUNTIF('Digital Craft'!$B:$B,"Bronze") | F18: =COUNTIF('Digital Craft'!$B:$B,"Titanium Grand Prix")+COUNTIF('Digital Craft'!$B:$B,"Titanium") | G18: =SUM(B18:F18)
A19: Film Craft | B19: =COUNTIF('Film Craft'!$B:$B,"Grand Prix") | C19: =COUNTIF('Film Craft'!$B:$B,"Gold") | D19: =COUNTIF('Film Craft'!$B:$B,"Silver") | E19: =COUNTIF('Film Craft'!$B:$B,"Bronze") | F19: =COUNTIF('Film Craft'!$B:$B,"Titanium Grand Prix")+COUNTIF('Film Craft'!$B:$B,"Titanium") | G19: =SUM(B19:F19)
A20: Industry Craft | B20: =COUNTIF('Industry Craft'!$B:$B,"Grand Prix") | C20: =COUNTIF('Industry Craft'!$B:$B,"Gold") | D20: =COUNTIF('Industry Craft'!$B:$B,"Silver") | E20: =COUNTIF('Industry Craft'!$B:$B,"Bronze") | F20: =COUNTIF('Industry Craft'!$B:$B,"Titanium Grand Prix")+COUNTIF('Industry Craft'!$B:$B,"Titanium") | G20: =SUM(B20:F20)
A21: Creative B2B | B21: =COUNTIF('Creative B2B'!$B:$B,"Grand Prix") | C21: =COUNTIF('Creative B2B'!$B:$B,"Gold") | D21: =COUNTIF('Creative B2B'!$B:$B,"Silver") | E21: =COUNTIF('Creative B2B'!$B:$B,"Bronze") | F21: =COUNTIF('Creative B2B'!$B:$B,"Titanium Grand Prix")+COUNTIF('Creative B2B'!$B:$B,"Titanium") | G21: =SUM(B21:F21)
A22: Creative Data | B22: =COUNTIF('Creative Data'!$B:$B,"Grand Prix") | C22: =COUNTIF('Creative Data'!$B:$B,"Gold") | D22: =COUNTIF('Creative Data'!$B:$B,"Silver") | E22: =COUNTIF('Creative Data'!$B:$B,"Bronze") | F22: =COUNTIF('Creative Data'!$B:$B,"Titanium Grand Prix")+COUNTIF('Creative Data'!$B:$B,"Titanium") | G22: =SUM(B22:F22)
A23: Direct | B23: =COUNTIF('Direct'!$B:$B,"Grand Prix") | C23: =COUNTIF('Direct'!$B:$B,"Gold") | D23: =COUNTIF('Direct'!$B:$B,"Silver") | E23: =COUNTIF('Direct'!$B:$B,"Bronze") | F23: =COUNTIF('Direct'!$B:$B,"Titanium Grand Prix")+COUNTIF('Direct'!$B:$B,"Titanium") | G23: =SUM(B23:F23)
A24: Media | B24: =COUNTIF('Media'!$B:$B,"Grand Prix") | C24: =COUNTIF('Media'!$B:$B,"Gold") | D24: =COUNTIF('Media'!$B:$B,"Silver") | E24: =COUNTIF('Media'!$B:$B,"Bronze") | F24: =COUNTIF('Media'!$B:$B,"Titanium Grand Prix")+COUNTIF('Media'!$B:$B,"Titanium") | G24: =SUM(B24:F24)
A25: PR | B25: =COUNTIF('PR'!$B:$B,"Grand Prix") | C25: =COUNTIF('PR'!$B:$B,"Gold") | D25: =COUNTIF('PR'!$B:$B,"Silver") | E25: =COUNTIF('PR'!$B:$B,"Bronze") | F25: =COUNTIF('PR'!$B:$B,"Titanium Grand Prix")+COUNTIF('PR'!$B:$B,"Titanium") | G25: =SUM(B25:F25)
A26: Social & Creator | B26: =COUNTIF('Social & Creator'!$B:$B,"Grand Prix") | C26: =COUNTIF('Social & Creator'!$B:$B,"Gold") | D26: =COUNTIF('Social & Creator'!$B:$B,"Silver") | E26: =COUNTIF('Social & Creator'!$B:$B,"Bronze") | F26: =COUNTIF('Social & Creator'!$B:$B,"Titanium Grand Prix")+COUNTIF('Social & Creator'!$B:$B,"Titanium") | G26: =SUM(B26:F26)
A27: Entertainment | B27: =COUNTIF('Entertainment'!$B:$B,"Grand Prix") | C27: =COUNTIF('Entertainment'!$B:$B,"Gold") | D27: =COUNTIF('Entertainment'!$B:$B,"Silver") | E27: =COUNTIF('Entertainment'!$B:$B,"Bronze") | F27: =COUNTIF('Entertainment'!$B:$B,"Titanium Grand Prix")+COUNTIF('Entertainment'!$B:$B,"Titanium") | G27: =SUM(B27:F27)
A28: Entertainment Lions for Gaming | B28: =COUNTIF('Entertainment Lions for Gaming'!$B:$B,"Grand Prix") | C28: =COUNTIF('Entertainment Lions for Gaming'!$B:$B,"Gold") | D28: =COUNTIF('Entertainment Lions for Gaming'!$B:$B,"Silver") | E28: =COUNTIF('Entertainment Lions for Gaming'!$B:$B,"Bronze") | F28: =COUNTIF('Entertainment Lions for Gaming'!$B:$B,"Titanium Grand Prix")+COUNTIF('Entertainment Lions for Gaming'!$B:$B,"Titanium") | G28: =SUM(B28:F28)
A29: Entertainment Lions for Music | B29: =COUNTIF('Entertainment Lions for Music'!$B:$B,"Grand Prix") | C29: =COUNTIF('Entertainment Lions for Music'!$B:$B,"Gold") | D29: =COUNTIF('Entertainment Lions for Music'!$B:$B,"Silver") | E29: =COUNTIF('Entertainment Lions for Music'!$B:$B,"Bronze") | F29: =COUNTIF('Entertainment Lions for Music'!$B:$B,"Titanium Grand Prix")+COUNTIF('Entertainment Lions for Music'!$B:$B,"Titanium") | G29: =SUM(B29:F29)
A30: Entertainment Lions for Sport | B30: =COUNTIF('Entertainment Lions for Sport'!$B:$B,"Grand Prix") | C30: =COUNTIF('Entertainment Lions for Sport'!$B:$B,"Gold") | D30: =COUNTIF('Entertainment Lions for Sport'!$B:$B,"Silver") | E30: =COUNTIF('Entertainment Lions for Sport'!$B:$B,"Bronze") | F30: =COUNTIF('Entertainment Lions for Sport'!$B:$B,"Titanium Grand Prix")+COUNTIF('Entertainment Lions for Sport'!$B:$B,"Titanium") | G30: =SUM(B30:F30)
A31: Brand Experience & Activation | B31: =COUNTIF('Brand Experience & Activation'!$B:$B,"Grand Prix") | C31: =COUNTIF('Brand Experience & Activation'!$B:$B,"Gold") | D31: =COUNTIF('Brand Experience & Activation'!$B:$B,"Silver") | E31: =COUNTIF('Brand Experience & Activation'!$B:$B,"Bronze") | F31: =COUNTIF('Brand Experience & Activation'!$B:$B,"Titanium Grand Prix")+COUNTIF('Brand Experience & Activation'!$B:$B,"Titanium") | G31: =SUM(B31:F31)
A32: Creative Business Transformation | B32: =COUNTIF('Creative Bus. Transformation'!$B:$B,"Grand Prix") | C32: =COUNTIF('Creative Bus. Transformation'!$B:$B,"Gold") | D32: =COUNTIF('Creative Bus. Transformation'!$B:$B,"Silver") | E32: =COUNTIF('Creative Bus. Transformation'!$B:$B,"Bronze") | F32: =COUNTIF('Creative Bus. Transformation'!$B:$B,"Titanium Grand Prix")+COUNTIF('Creative Bus. Transformation'!$B:$B,"Titanium") | G32: =SUM(B32:F32)
A33: Creative Commerce | B33: =COUNTIF('Creative Commerce'!$B:$B,"Grand Prix") | C33: =COUNTIF('Creative Commerce'!$B:$B,"Gold") | D33: =COUNTIF('Creative Commerce'!$B:$B,"Silver") | E33: =COUNTIF('Creative Commerce'!$B:$B,"Bronze") | F33: =COUNTIF('Creative Commerce'!$B:$B,"Titanium Grand Prix")+COUNTIF('Creative Commerce'!$B:$B,"Titanium") | G33: =SUM(B33:F33)
A34: Innovation | B34: =COUNTIF('Innovation'!$B:$B,"Grand Prix") | C34: =COUNTIF('Innovation'!$B:$B,"Gold") | D34: =COUNTIF('Innovation'!$B:$B,"Silver") | E34: =COUNTIF('Innovation'!$B:$B,"Bronze") | F34: =COUNTIF('Innovation'!$B:$B,"Titanium Grand Prix")+COUNTIF('Innovation'!$B:$B,"Titanium") | G34: =SUM(B34:F34)
A35: Luxury | B35: =COUNTIF('Luxury'!$B:$B,"Grand Prix") | C35: =COUNTIF('Luxury'!$B:$B,"Gold") | D35: =COUNTIF('Luxury'!$B:$B,"Silver") | E35: =COUNTIF('Luxury'!$B:$B,"Bronze") | F35: =COUNTIF('Luxury'!$B:$B,"Titanium Grand Prix")+COUNTIF('Luxury'!$B:$B,"Titanium") | G35: =SUM(B35:F35)
A36: Glass: The Lion for Change | B36: =COUNTIF('Glass - The Lion for Change'!$B:$B,"Grand Prix") | C36: =COUNTIF('Glass - The Lion for Change'!$B:$B,"Gold") | D36: =COUNTIF('Glass - The Lion for Change'!$B:$B,"Silver") | E36: =COUNTIF('Glass - The Lion for Change'!$B:$B,"Bronze") | F36: =COUNTIF('Glass - The Lion for Change'!$B:$B,"Titanium Grand Prix")+COUNTIF('Glass - The Lion for Change'!$B:$B,"Titanium") | G36: =SUM(B36:F36)
A37: Grand Prix for Good | B37: =COUNTIF('Grand Prix for Good'!$B:$B,"Grand Prix") | C37: =COUNTIF('Grand Prix for Good'!$B:$B,"Gold") | D37: =COUNTIF('Grand Prix for Good'!$B:$B,"Silver") | E37: =COUNTIF('Grand Prix for Good'!$B:$B,"Bronze") | F37: =COUNTIF('Grand Prix for Good'!$B:$B,"Titanium Grand Prix")+COUNTIF('Grand Prix for Good'!$B:$B,"Titanium") | G37: =SUM(B37:F37)
A38: Sustainable Development Goals | B38: =COUNTIF('Sustainable Development Goals'!$B:$B,"Grand Prix") | C38: =COUNTIF('Sustainable Development Goals'!$B:$B,"Gold") | D38: =COUNTIF('Sustainable Development Goals'!$B:$B,"Silver") | E38: =COUNTIF('Sustainable Development Goals'!$B:$B,"Bronze") | F38: =COUNTIF('Sustainable Development Goals'!$B:$B,"Titanium Grand Prix")+COUNTIF('Sustainable Development Goals'!$B:$B,"Titanium") | G38: =SUM(B38:F38)
A39: Health & Wellness | B39: =COUNTIF('Health & Wellness'!$B:$B,"Grand Prix") | C39: =COUNTIF('Health & Wellness'!$B:$B,"Gold") | D39: =COUNTIF('Health & Wellness'!$B:$B,"Silver") | E39: =COUNTIF('Health & Wellness'!$B:$B,"Bronze") | F39: =COUNTIF('Health & Wellness'!$B:$B,"Titanium Grand Prix")+COUNTIF('Health & Wellness'!$B:$B,"Titanium") | G39: =SUM(B39:F39)
A40: Lions Health Grand Prix for Good | B40: =COUNTIF('Health Grand Prix for Good'!$B:$B,"Grand Prix") | C40: =COUNTIF('Health Grand Prix for Good'!$B:$B,"Gold") | D40: =COUNTIF('Health Grand Prix for Good'!$B:$B,"Silver") | E40: =COUNTIF('Health Grand Prix for Good'!$B:$B,"Bronze") | F40: =COUNTIF('Health Grand Prix for Good'!$B:$B,"Titanium Grand Prix")+COUNTIF('Health Grand Prix for Good'!$B:$B,"Titanium") | G40: =SUM(B40:F40)
A41: Pharma | B41: =COUNTIF('Pharma'!$B:$B,"Grand Prix") | C41: =COUNTIF('Pharma'!$B:$B,"Gold") | D41: =COUNTIF('Pharma'!$B:$B,"Silver") | E41: =COUNTIF('Pharma'!$B:$B,"Bronze") | F41: =COUNTIF('Pharma'!$B:$B,"Titanium Grand Prix")+COUNTIF('Pharma'!$B:$B,"Titanium") | G41: =SUM(B41:F41)
A42: Creative Effectiveness | B42: =COUNTIF('Creative Effectiveness'!$B:$B,"Grand Prix") | C42: =COUNTIF('Creative Effectiveness'!$B:$B,"Gold") | D42: =COUNTIF('Creative Effectiveness'!$B:$B,"Silver") | E42: =COUNTIF('Creative Effectiveness'!$B:$B,"Bronze") | F42: =COUNTIF('Creative Effectiveness'!$B:$B,"Titanium Grand Prix")+COUNTIF('Creative Effectiveness'!$B:$B,"Titanium") | G42: =SUM(B42:F42)
...

Sheet Creative Brand
A1: Year | B1: Tier | C1: Campaign | D1: Brand | E1: Product/Service | F1: Agency | G1: Country | H1: Subcategory | I1: Image URL | J1: YouTube ID | K1: Campaign Group | L1: Entry URL | M1: Description | N1: Keywords
A2: 2026 | B2: Grand Prix | C2: ABInBev: Creativity at Scale | D2: ABInBev | E2: Beer | F2: Anheuser-Busch InBev | G2: Belgium | H2: A01 - Talent & Workplace Culture | I2: https://ascentialcdn.filespin.io/api/v1/conversion/6313b7c3fac0443297698d064dc6d5ed | L2: https://www.lovethework.com/work/entries/abinbev-creativity-at-scale-792758 | M2: AB InBev's entry in the inaugural Creative Brand category, which judges the systems, culture and capabilities behind a brand's creative output rather than any single campaign. It lays out how the world's largest brewer turned creativity into a repeatable, company-wide discipline — shared creative principles, talent development and consistent ways of working embedded across its portfolio of beer brands and dozens of markets, so award-level work becomes a structured, ongoing growth capability rather than a one-off. | N2: creative-brand, talent, workplace-culture, creative-transformation, marketing-operations, organizational-culture, beer, alcohol, abinbev, global, belgium
A3: 2026 | B3: Gold | C3: Mastercard | D3: Mastercard | E3: Mastercard | F3: Mastercard | G3: United States | H3: A02 - Collaboration and Partnership Models | I3: https://ascentialcdn.filespin.io/api/v1/conversion/d6b76a71d79a4ae68f925ead9e28a8eb | L3: https://www.lovethework.com/work/entries/mastercard-779685 | M3: Mastercard's entry in the new Creative Brand category, recognising the operating model behind its marketing rather than a single execution. It centres on how the brand is built through long-term collaboration and partnership — sponsorships, cultural platforms and co-creation with outside organisations — turning those relationships into a consistent, repeatable system for staying culturally relevant and extending the brand across markets over time. | N3: creative-brand, collaboration, partnership, brand-platform, sponsorship, marketing-operations, payments, fintech, financial-services, finance, mastercard, united-states

Sheet Audio & Radio
A1: Year | B1: Tier | C1: Campaign | D1: Brand | E1: Product/Service | F1: Agency | G1: Country | H1: Subcategory | I1: Image URL | J1: YouTube ID | K1: Campaign Group | L1: Entry URL | M1: Description | N1: Keywords
A2: 2025 | B2: Grand Prix | C2: One Second Ads | D2: Budweiser | E2: Beer | F2: Africa Creative DDB | G2: Brazil | H2: B01 - Use of Music | I2: digital-presentation-images/audio-and-radio-budweiser-one-second-ads.webp | J2: RpvlshoKIrE | L2: https://www.lovethework.com/work/entries/one-second-ads-741948 | M2: A series of one-second social media ads built around the opening note or two of globally recognized songs — from Beyoncé and Taylor Swift to The Beatles and Foo Fighters — short enough that true fans could identify the track but too brief to trigger music licensing fees. Budweiser challenged viewers on social media to name the song, rewarding correct guessers with a beer coupon sent via DM, which turned the comment sections into active guessing threads and kept viewers replaying the ads voluntarily. | N2: beer, alcohol, social-media, audio, music, entertainment, short-form-video, brazil, user-participation, mobile
A3: 2025 | B3: Gold | C3: Name This Oreo | D3: Oreo | E3: Oreo | F3: VML | G3: United States | H3: A03 - Voice Activation | I3: digital-presentation-images/audio-and-radio-oreo-name-this-oreo.webp | J3: hRp6cBmbfIw | L3: https://www.lovethework.com/work/entries/name-this-oreo-741853 | M3: A voice-activated web game at namethisoreo.com that turns 'OREO Grammar' — a viral internet meme in which cookie-and-creme combinations are read aloud as sequences of 'O' (cookie) and 'RE' (creme) — into a timed naming challenge. Players speak the correct O-RE sequence for each stacked OREO combination shown on screen, build streaks, and unlock cookie offers. | N3: cookie, snack, food, packaged-goods, cpg, fmcg, voice-game, web-experience, meme-marketing, gamification, audio, united-states
A4: 2025 | B4: Gold | C4: One Second Ads | D4: Budweiser | E4: Beer | F4: Africa Creative DDB | G4: Brazil | H4: A06 - Audio-Led Creativity | I4: digital-presentation-images/audio-and-radio-budweiser-one-second-ads.webp | J4: RpvlshoKIrE | L4: https://www.lovethework.com/work/entries/one-second-ads-741888 | M4: A series of one-second social media ads built around the opening note or two of globally recognized songs — from Beyoncé and Taylor Swift to The Beatles and Foo Fighters — short enough that true fans could identify the track but too brief to trigger music licensing fees. Budweiser challenged viewers on social media to name the song, rewarding correct guessers with a beer coupon sent via DM, which turned the comment sections into active guessing threads and kept viewers replaying the ads voluntarily. | N4: beer, alcohol, social-media, audio, music, entertainment, short-form-video, brazil, user-participation, mobile
A5: 2025 | B5: Gold | C5: The Second Release | D5: Billboard Arabia | E5: Billboard Magazine | F5: SRMG Labs | G5: Saudi Arabia | H5: C03 - Single-Market Campaign | I5: digital-presentation-images/audio-and-radio-billboard-arabia-the-second-release.webp | J5: sH5Jk7ywBLc | L5: https://www.lovethework.com/work/entries/the-second-release-742149 | M5: A vinyl record pressing of 'Etab,' a 1988 Saudi classic by singer Tarouf Abdulkhair Adam Talal (stage name Etab), remastered and re-released in 2024 by Billboard Arabia to mark Saudi National Day — the song's first-ever physical release. | N5: music, entertainment, vinyl, audio, cultural-engagement, saudi-arabia, music-media, re-release, archival
A6: 2025 | B6: Silver | C6: Name This Oreo | D6: Oreo | E6: Oreo | F6: VML | G6: United States | H6: A01 - Use of Audio & Radio as a Medium | I6: digital-presentation-images/audio-and-radio-oreo-name-this-oreo.webp | J6: hRp6cBmbfIw | L6: https://www.lovethework.com/work/entries/name-this-oreo-741778 | M6: A voice-activated web game at namethisoreo.com that turns "OREO Grammar" — a viral internet meme in which cookie-and-creme combinations are read aloud as sequences of "O" (cookie) and "RE" (creme) — into a timed naming challenge. Players speak the correct O-RE sequence for each stacked OREO combination shown on screen, build streaks, and unlock cookie offers. The campaign launched in partnership with TikTok's 2024 Creator of the Year, @OHIOSATOYUBOSS, whose existing OREO Grammar content made him the natural host. | N6: snack, food, packaged-goods, cpg, fmcg, voice-activation, mobile-app, social-influencer, gamification, united-states, tiktok, audio
A7: 2025 | B7: Silver | C7: Fishermen Storytellers | D7: Corona | E7: Beer | F7: Africa Creative DDB | G7: Brazil | H7: A04 - Branded Content/Podcasts | I7: digital-presentation-images/audio-and-radio-corona-fishermen-storytellers.webp | J7: vimeo:1090130974 | L7: https://www.lovethework.com/work/entries/fishermen-storytellers-764514 | M7: A documentary and design project that helps Brazilian fishing communities replace lost income during the annual fishing ban by training fishermen as tour guides for their own folklore. The work culminates in a stop-motion film made from hand-carved wooden scenes and a book bound in salvaged boat wood, fishing nets, and cement. | N7: branded-content, social-good, craft, storytelling, beer, alcohol, brazil, sustainability, stop-motion
A8: 2025 | B8: Silver | C8: 1. High Energy Intern | D8: Fusion Energy Drink | E8: Energy Drink | F8: David | G8: Spain | H8: B03 - Script | I8: https://ascentialcdn.filespin.io/api/v1/storyboard/846afe3e468240929823119e42cf3b99/storyboard_000008.jpg | J8: vimeo:1105218555 | L8: https://www.lovethework.com/work/entries/1-high-energy-intern-762404 | M8: A radio campaign for Fusion Energy Drink that flips the usual category logic: it's not for high-energy people, it's for the people who have to keep up with them. In this spot, 'High-Energy Intern' becomes a lovable but relentless office sunbeam—firing off endless questions, emoji-packed messages, and 'OMG amazing' reactions to even the dullest policy update. Fusion is energy for people who live with people with energy—or in this case, work 40 hours a week directly across from them. | N8: energy-drink, drinks, beverage, radio, audio, humor, workplace, brand-platform
A9: 2025 | B9: Silver | C9: Chill Enough | D9: Coors Brewing Company | E9: Coors Light | F9: Alma Advertising Agency | G9: United States | H9: B04 - Casting & Performance | I9: digital-presentation-images/audio-and-radio-coors-light-chill-enough.webp | J9: vimeo:1086177966 | L9: https://www.lovethework.com/work/entries/chill-enough-762433 | M9: A radio campaign in which voiceover announcers recorded their scripts while fully submerged in ice plunge baths — the physical discomfort of the cold translating directly into audible distress, bleeps, and involuntary reactions in the final spots. The stunt mirrors Coors Light's cold-activated can, whose mountain label turns blue only when the beer reaches ice-cold temperature. | N9: beer, alcohol, radio, casting-and-performance, stunt, united-states, audio, brand-feature
A10: 2025 | B10: Silver | C10: Burger to King | D10: Burger King | E10: Burger King | F10: Happiness, an FCB Alliance | G10: Belgium | H10: C02 - Challenger Brand | I10: digital-presentation-images/audio-and-radio-burger-king-burger-to-king.webp | J10: RQVaoU4CGRk | L10: https://www.lovethework.com/work/entries/burger-to-king-763482 | M10: A loophole in EA FC25's AI commentary system, which dynamically reads every real player's name aloud, exploited by Burger King. Fans were coached via influencers and social posts to build Ultimate Team squads using real FC25 players actually named 'Burger' (e.g. Wouter Burger, Stoke City) and 'King' (e.g. Joshua King, Toulouse), so that whenever the ball moved between them, the automated in-game commentator called out 'Burger... King' — without EA Sports' involvement. | N10: qsr, fast-food, restaurant, food, gaming, video-games, entertainment, football, soccer, sport, audio, in-game, social-media, ambient, hijack
A11: 2025 | B11: Silver | C11: The Second Release | D11: Billboard Arabia | E11: Billboard Magazine | F11: SRMG Labs | G11: Saudi Arabia | H11: C04 - Social Behaviour | I11: digital-presentation-images/audio-and-radio-billboard-arabia-the-second-release.webp | J11: sH5Jk7ywBLc | L11: https://www.lovethework.com/work/entries/the-second-release-742142 | M11: A vinyl record pressing of "Etab," a 1988 Saudi classic by singer Tarouf Abdulkhair Adam Talal (stage name Etab), remastered and re-released in 2024 by Billboard Arabia to mark Saudi National Day — the song's first-ever physical release. The packaging, designed by SRMG Labs in Riyadh, pairs archival black-and-white portrait photography with neon-green Arabic and Latin typography across the sleeve, inner labels, and inserts. | N11: billboard-magazine, music, entertainment, vinyl, packaging, arabic-typography, heritage, saudi-arabia, single-market-campaign, print
A12: 2025 | B12: Silver | C12: From Hurt to Hit | D12: Brahma | E12: Beer | F12: Africa Creative DDB | G12: Brazil | H12: C05 - Use of Humour | I12: https://ascentialcdn.filespin.io/api/v1/conversion/2c4c0601d34e42cf931304cf072f6fa8 | J12: vimeo:1081566541 | L12: https://www.lovethework.com/work/entries/from-hurt-to-hit-742107 | M12: A campaign built around the Brazilian sertanejo tradition of writing songs about heartbreak: Brahma collected real emotional stories from consumers and turned them into sertanejo tracks, connecting the brand to the country's most popular music genre through the raw material of personal pain. In Brazil, where alcohol advertising operates under a "dark market" restriction that bans direct product promotion, associating with music culture is one of the few open channels — making the emotional honesty of the mechanic both the creative idea and the regulatory workaround. | N12: beer, alcohol, audio, music, entertainment, sertanejo, humor, brazil, branded-content, user-generated-content
A13: 2025 | B13: Silver | C13: Me Feat. Me | D13: Nosotras | E13: Nosotras | F13: DDB Chile | G13: Chile | H13: C09 - Cultural Engagement | I13: https://ascentialcdn.filespin.io/api/v1/conversion/a6ac5c5dd4fc4487966ae01ac52f95ff | J13: KBcSEzHf5DA | L13: https://www.lovethework.com/work/entries/me-feat-me-742031 | M13: A music track in which Nosotras recruited women to collaborate with themselves — each artist featured as both the lead and the featured act, credited as "Me feat. Me" — to express self-confidence as a solo identity rather than one defined in relation to others. The format borrowed the standard music-industry "feat." credit convention to make the idea literal: the only collaborator worth naming is yourself. | N13: feminine-hygiene, audio, music, entertainment, cultural-engagement, womens-empowerment, chile
... A22: 2025 | B22: Bronze | C22: Sounds Right | D22: Museum for the United Nations - UN Live | E22: Music | F22: AKQA | G22: Denmark | H22: C07 - Corporate Purpose & Social Responsibility | I22: digital-presentation-images/audio-and-radio-museum-for-the-united-nations-sounds-right.webp | J22: 5newTxSZ9bU | L22: https://www.lovethework.com/work/entries/sounds-right-759882 | M22: A Spotify initiative, developed by AKQA for Museum for the United Nations – UN Live, that registers NATURE as an official credited artist on the platform — so that existing songs featuring natural soundscapes, from artists including V of BTS, David Bowie, Brian Eno, AURORA, and Ellie Goulding, list NATURE as a collaborator with its own verified artist profile. Streaming royalties attributed to NATURE's credit are directed toward nature conservation funding. | N22: music, entertainment, streaming, tv, spotify, mobile-app, conservation, public-service, corporate-social-responsibility, denmark, akqa
A23: 2025 | B23: Silver | C23: 2. High Energy Boyfriend | D23: Fusion Energy Drink | F23: David | G23: Spain | H23: B03 - Script | I23: https://ascentialcdn.filespin.io/api/v1/storyboard/846afe3e468240929823119e42cf3b99/storyboard_000008.jpg | J23: vimeo:1105218613 | M23: A radio campaign for Fusion Energy Drink that flips the usual category logic: it's not for high-energy people, it's for the people who have to keep up with them. In this spot, 'High-Energy Boyfriend' becomes a lovable but exhausting social tornado—filling your apartment with friends, turning every weekend into an event, and somehow volunteering you both for Dimitri's wedding and a neighbor's pregnant cat. Fusion is energy for people who live with people with energy—and their friends, and their friends' friends. | N23: energy-drink, drinks, beverage, radio, audio, humor, brand-platform
A24: 2025 | B24: Silver | C24: 3. High Energy Dad | D24: Fusion Energy Drink | F24: David | G24: Spain | H24: B03 - Script | I24: https://ascentialcdn.filespin.io/api/v1/storyboard/846afe3e468240929823119e42cf3b99/storyboard_000008.jpg | J24: vimeo:1105218658 | M24: A radio campaign for Fusion Energy Drink that flips the usual category logic: it's not for high-energy people, it's for the people who have to keep up with them. In this spot, 'High-Energy Dad' becomes a lovable but exhausting force of nature—turning errands, chores and life lessons into full-body cardio. Fusion is energy for people who live with people with energy. | N24: energy-drink, drinks, beverage, radio, audio, humor, family, brand-platform
A25: 2025 | B25: Silver | C25: Cold Detector | D25: Coors Brewing Company | F25: Alma Advertising Agency | G25: United States | H25: B04 - Casting & Performance | I25: digital-presentation-images/audio-and-radio-coors-light-chill-enough.webp | J25: vimeo:1086178012 | M25: A radio campaign in which voiceover announcers recorded their scripts while submerged in ice plunge baths — a live demonstration of the cold the Coors Light cold-activated can is designed to signal. The physical shock of the ice water produced involuntary reactions, bleeps, and audibly frozen delivery across three finished spots. | N25: beer, alcohol, radio, casting, united-states, audio, experiential-production, cold-activation, packaging-tie-in
A26: 2025 | B26: Silver | C26: Mountain Cold | D26: Coors Brewing Company | F26: Alma Advertising Agency | G26: United States | H26: B04 - Casting & Performance | I26: digital-presentation-images/audio-and-radio-coors-light-chill-enough.webp | J26: vimeo:1086178036 | M26: A radio campaign in which voiceover announcers record Coors Light scripts from inside an ice plunge — submerged to the shoulders in ice-cold water for the duration of each take. Three spots were produced, each capturing the involuntary reactions, strained delivery, and bleeped expletives of announcers trying to maintain professional composure while experiencing the same cold the brand's color-changing mountain label is designed to signal. | N26: beer, alcohol, radio, casting-and-performance, stunt, united-states, audio, coors-light
A27: 2025 | B27: Bronze | C27: Spill the Tea | D27: Hansa Pilsener | F27: Joe Public | G27: South Africa | H27: B03 - Script | I27: https://ascentialcdn.filespin.io/api/v1/storyboard/0bca684772274dd9a6e2c0c6cd401876/storyboard_000008.jpg | J27: vimeo:1032236549 | M27: A radio campaign from Hansa Pilsner, which positions itself as the beer for grown men by lovingly roasting younger guys and their try-hard trends—from 'spill the tea' to gaming streams, sneaker collecting and ASMR sleep videos. The spot builds a funny exclusionary platform: there may be 'a beer for you,' but Hansa is reserved for men with a little more life experience. | N27: beer, alcohol, radio, audio, humor, south-africa, brand-platform
A28: 2025 | B28: Bronze | C28: Okrrr | D28: Hansa Pilsener | F28: Joe Public | G28: South Africa | H28: B03 - Script | I28: https://ascentialcdn.filespin.io/api/v1/storyboard/0bca684772274dd9a6e2c0c6cd401876/storyboard_000008.jpg | J28: vimeo:1022471976 | M28: A radio campaign from Hansa Pilsner, which positions itself as the beer for grown men by lovingly roasting younger guys and their try-hard trends—from personal brands, oversized fits, TikTok challenges, and get-ready-with-me culture. The spot builds a funny exclusionary platform: there may be 'a beer for you,' but Hansa is reserved for men with a little more life experience. | N28: beer, alcohol, radio, audio, humor, south-africa, brand-platform
A29: 2026 | B29: Grand Prix | C29: Coquí Alarmed | D29: Hyundai Puerto Rico | E29: Hyundai | F29: BBDO Puerto Rico | G29: Puerto Rico | H29: C03 - Single-Market Campaign | I29: https://ascentialcdn.filespin.io/api/v1/conversion/6d4d0b7e5bcc4ec58a29958dcba0a0c2 | J29: 55knFa5zP6g | L29: https://www.lovethework.com/work/entries/coqu-alarmed-780472 | M29: After a tourist complained online about the noise of Puerto Rico's coquí, Hyundai replaced the standard lock and unlock chirp in its rental cars at Avis, Enterprise and Charlie Car Rental with the real recorded call of the tiny tree frog. Neck hangers in each car explained the coquí's place in Puerto Rican identity, turning a functional alert sound into a piece of national pride. | N29: automotive, cars, transport, car-rental, vehicles, audio, sound-design, sonic-branding, cultural-identity, tourism, travel, wildlife, nature, hyundai, puerto-rico
A30: 2026 | B30: Gold | C30: Sleep Talk Reviews | D30: IKEA | E30: IKEA | F30: Rethink | G30: Canada | H30: A06 - Audio-Led Creativity | I30: https://ascentialcdn.filespin.io/api/v1/conversion/29d5e6beff5343f4a75840aacad3165f | J30: BNAfX0lKSjg | L30: https://www.lovethework.com/work/entries/sleep-talk-reviews-780352 | M30: IKEA invited real sleep talkers to spend the night on its mattresses inside the store, with hidden mics capturing their mumbles, snores and sleep-talk as honest reviews of how deeply they slept. The recordings ran on radio, streaming audio, social and out-of-home, reframing deep sleep itself as proof of comfort. | N30: furniture, home, homeware, retail, mattresses, bedding, audio, sound-recording, product-reviews, sleep, ikea, canada
A31: 2026 | B31: Gold | C31: Searching For Birds On Wires | D31: Abradee | E31: Institutional | F31: Africa Creative | G31: Brazil | H31: B01 - Use of Music | I31: https://ascentialcdn.filespin.io/api/v1/conversion/5b453c1cca9944e59a8d6df49dabd9f2 | J31: vimeo:1202133381 | L31: https://www.lovethework.com/work/entries/searching-for-birds-on-wires-780318 | M31: For Brazil's electricity-distribution association, Africa Creative turned photographs of birds perched on power lines into music, reading each bird's position on the wires as a note on a musical staff and composing an original piece from the patterns the birds formed. | N31: energy, electricity, utilities, power, institutional, audio, music, entertainment, composition, birds, nature, power-lines, abradee, brazil
A32: 2026 | B32: Silver | C32: A Mother's Commentary | D32: Reporters Without Borders (RSF) | E32: Press Freedom Advocacy | F32: The Good Company | G32: France | H32: A01 - Use of Audio & Radio as a Medium | I32: https://ascentialcdn.filespin.io/api/v1/conversion/e5b4c80d95974dff83d0dba8bc80f740 | J32: a4ZCQDgxW0U | L32: https://www.lovethework.com/work/entries/a-mothers-commentary-780310 | M32: During a Paris Saint-Germain match on beIN Sports, the broadcast's live commentary cut out at the seventh minute - one minute for each year of his sentence - and was replaced by the voice of Sylvie Godard, mother of detained French sports journalist Christophe Gleizes. She spoke to viewers and then to her son, who can only follow football from his Algerian prison cell, as part of RSF's push for his release. | N32: non-profit, ngo, not-for-profit, charity, social-good, press-freedom, journalism, human-rights, advocacy, audio, radio, broadcast, entertainment, sports, football, soccer, sport, rsf, france
A33: 2026 | B33: Silver | C33: The Unofficial Official Sound Of F1 | D33: Sting | E33: Sting | F33: Leo India | G33: India | H33: C02 - Challenger Brand | I33: https://ascentialcdn.filespin.io/api/v1/conversion/c8ed916715884400910e742f565dc00e | J33: MteFVMaD-0M | L33: https://www.lovethework.com/work/entries/the-unofficial-official-sound-of-f1-774255 | M33: To launch Sting's Formula 1 partnership, the brand seized on a fan observation that an F1 engine's roar sounds like the word 'Sting.' DJ Armin van Buuren claimed he could hear 'Stinggg' hidden in the engine noise, sparking remixes and debate, and the idea extended into a track built from real race audio. | N33: beverage, drinks, energy-drink, soft-drink, audio, sound, music, entertainment, sports, motorsport, sport, racing, formula-1, sponsorship, sting, india
A34: 2026 | B34: Silver | C34: Could Have Been A Heineken | D34: Heineken | E34: Heineken Beer | F34: LePub | G34: Italy | H34: C04 - Social Behaviour | I34: https://ascentialcdn.filespin.io/api/v1/conversion/325cbd01df444a49a6a09ac2bc5dd3fa | J34: vimeo:1203492482 | L34: https://www.lovethework.com/work/entries/could-have-been-a-heineken-780519 | M34: To nudge people off endless voice notes and back into face-to-face conversation, Heineken let users forward any voice message longer than three minutes to a private WhatsApp bot. The bot replied 'Could have been a Heineken' with a voucher for a free beer and suggestions for nearby bars. | N34: beer, alcohol, beverage, drinks, audio, voice-messaging, messaging, technology, social-connection, heineken, italy
A35: 2026 | B35: Silver | C35: Doorbell Ads | D35: Mercado Libre | E35: Mercado Libre | F35: GUT | G35: Argentina | H35: C06 - Breakthrough on a Budget | I35: https://ascentialcdn.filespin.io/api/v1/conversion/7b5cd9b3d33e45f7a2d41fc540a4f415 | J35: vimeo:1187878678 | L35: https://www.lovethework.com/work/entries/doorbell-ads-780499 | M35: Mercado Libre bought radio spots as short as a doorbell chime and placed them to run last in the ad break, so the brief 'ding' reframed every commercial before it: whatever had just been advertised could be found on Mercado Libre. | N35: ecommerce, retail, online-shopping, marketplace, shopping, audio, radio, media-placement, mercado-libre, argentina
A36: 2026 | B36: Silver | C36: The Yangzhou Qiao Bei Musical Suite | D36: Yangzhou Municipal Bureau of Culture, Radio, TV and Tourism, China | E36: To Promote Bathhouse Culture and the City of Yangzhou | F36: TBWA\China | G36: China | H36: D04 - Travel, Leisure, Retail, Restaurants & Fast-Food Chains | I36: https://www.brandinginasia.com/wp-content/uploads/2026/05/Yangzhou-Qiao-Bei-Musical-Suite_board-copy.webp | J36: 2mH41-1bJVA | L36: https://www.lovethework.com/work/entries/the-yangzhou-qiao-bei-musical-suite-778657 | M36: TBWA China turned the towels of Yangzhou's 1,200-year-old Qiao Bei back-tapping bath ritual into percussion instruments, recording four original 'towel percussion' compositions from the massage rhythms. An NFC chip in the towel packaging let people unlock the music and learn the rhythms at home, promoting the city's bathhouse heritage and tourism. | N36: tourism, travel, government, culture, heritage, audio, music, entertainment, percussion, sound, china, yangzhou
A37: 2026 | B37: Bronze | C37: Played By Humans | D37: Jazz Is Dead | E37: Played By Humans | F37: TBWA\Chiat\Day | G37: United States | H37: B01 - Use of Music | I37: https://i.ytimg.com/vi/bz1r-JIEdzU/maxresdefault.jpg | J37: 1lZ696Kd6ic | L37: https://www.lovethework.com/work/entries/played-by-humans-774278 | M37: In response to AI-generated tracks flooding streaming platforms, Jazz Is Dead and TBWA\Chiat\Day created 'Played By Humans,' a stamp of authenticity and public verification platform that lets artists and listeners certify music as human-made. It launched with a documentary short and a human-made cover of an AI-generated song. | N37: music, entertainment, arts, culture, audio, ai, technology, artificial-intelligence, authenticity, verification, jazz-is-dead, united-states
A38: 2026 | B38: Bronze | C38: Healing Era | D38: Hansa Pilsener | E38: Hansa Pilsener | F38: Joe Public | G38: South Africa | H38: B03 - Script | I38: https://ascentialcdn.filespin.io/api/v1/storyboard/3e5b42d9dfa54b8da6f479b1e9630e4e/storyboard_000008.jpg | J38: cjAwhbK_ZBQ | L38: https://www.lovethework.com/work/entries/healing-era-780405 | M38: Part of Hansa Pilsener's over-30s 'You Deserve a Beer' platform, this radio script - voiced by South African comedian Mojak in an epic, affirming locker-room style - appears to celebrate Gen Z's 'healing era' of self-care as hard work, before a dry twist concludes they deserve a beer, just not a Hansa. | N38: beer, alcohol, beverage, drinks, audio, radio, script, humour, comedy, gen-z, hansa-pilsener, south-africa
A39: 2026 | B39: Bronze | C39: The Hustle | D39: Hansa Pilsener | E39: Hansa Pilsener | F39: Joe Public | G39: South Africa | H39: B03 - Script | I39: https://ascentialcdn.filespin.io/api/v1/storyboard/3ea2629528df4e4a87566afecb98c392/storyboard_000008.jpg | J39: cqUa2mLcc5o | L39: https://www.lovethework.com/work/entries/the-hustle-780321 | M39: Part of Hansa Pilsener's over-30s 'You Deserve a Beer' platform, this radio script - voiced by comedian Mojak in a grand, motivational tone - mock-celebrates Gen Z's idea of 'the hustle' as hard work, before a dry twist lands that they deserve a beer, just not a Hansa. | N39: beer, alcohol, beverage, drinks, audio, radio, script, humour, comedy, gen-z, hansa-pilsener, south-africa
A40: 2026 | B40: Bronze | C40: Delulu Is The Solulu | D40: Hansa Pilsener | E40: Hansa Pilsener | F40: Joe Public | G40: South Africa | H40: B03 - Script | I40: https://ascentialcdn.filespin.io/api/v1/storyboard/fdf7d8da65e240369ca734caac94542b/storyboard_000008.jpg | J40: mI3rWxtcblQ | L40: https://www.lovethework.com/work/entries/delulu-is-the-solulu-780328 | M40: Part of Hansa Pilsener's over-30s 'You Deserve a Beer' platform, this radio script leans on the Gen Z phrase 'delulu is the solulu,' voiced by comedian Mojak as a heroic affirmation of manifesting as effort, before the dry twist that they deserve a beer, just not a Hansa. | N40: beer, alcohol, beverage, drinks, audio, radio, script, humour, comedy, gen-z, slang, hansa-pilsener, south-africa
... A45: 2026 | B45: Bronze | C45: Bedtime Donations | D45: Royal Society For Blind Children | E45: Bedtime Donations App | F45: Innocean | G45: Germany | H45: D07 - Not-for-Profit / Charity / Government | I45: https://ascentialcdn.filespin.io/api/v1/conversion/f4c9dafd39714b8c96da0d7dd9e055ea | J45: nw12Kyu0wqQ | L45: https://www.lovethework.com/work/entries/bedtime-donations-780400 | M45: Innocean Berlin and the Royal Society for Blind Children built the Bedtime Donations app: when a parent reads a story from its library aloud, safe AI turns the reading into a free audiobook for blind and vision-impaired children to listen to anytime, crowdsourcing a growing library of bedtime stories. | N45: non-profit, charity, ngo, not-for-profit, social-good, accessibility, blindness, disability, children, audio, audiobooks, app, ai, technology, rsbc, germany

Sheet Film
A1: Year | B1: Tier | C1: Campaign | D1: Brand | E1: Product/Service | F1: Agency | G1: Country | H1: Subcategory | I1: Image URL | J1: YouTube ID | K1: Campaign Group | L1: Entry URL | M1: Description | N1: Keywords
A2: 2025 | B2: Grand Prix | C2: Paris Paralympics 2024: Considering What? | D2: Channel 4 | E2: Channel 4 | F2: Channel 4 | G2: United Kingdom | H2: A05 - Media/Entertainment | I2: digital-presentation-images/film-channel-4-paris-paralympic-2024-considering-what.webp | J2: bUs_mNTNwvE | L2: https://www.lovethework.com/work/entries/paris-paralympics-2024-considering-what-738686 | M2: A Channel 4 campaign for the Paris 2024 Paralympic Games, made by in-house agency 4Creative and production company Biscuit Filmworks, built around the patronising language real viewers use about Paralympic athletes — phrases like "she's incredibly fast for someone in a wheelchair" and "amazing... considering" — which appeared as OOH billboards with the condescending caveats crossed out by the athletes' actual sporting achievements. On social, the same treatment was flipped: patronising comments typically aimed at Paralympians were redirected at non-disabled Olympians, exposing the double standard. The campaign responded to research showing that 60% of viewers still watch the Paralympics primarily to see athletes "overcome" their disabilities rather than compete as elite sportspeople. | N2: broadcaster, ooh, social-media, paralympics, disability, sport, film, cinema, entertainment, united-kingdom, 4creative
A3: 2025 | B3: Grand Prix | C3: The Final Copy of Ilon Specht | D3: L'oréal Paris | E3: L'oréal Paris | F3: McCANN | G3: France | H3: F07 - Corporate Purpose & Social Responsibility | I3: digital-presentation-images/film-loreal-paris-the-final-copy-of-ilona-specht.webp | J3: vimeo:1094956645 | L3: https://www.lovethework.com/work/entries/the-final-copy-of-ilon-specht-739568 | M3: An 18-minute documentary released on International Women's Day across Prime Video, AMC+, and YouTube, telling the story of Ilon Specht — the copywriter who wrote "Because I'm Worth It" for L'Oréal Paris in 1973 — through an intimate, deathbed-style account. Made by McCann Paris with Proudfoot's Breakwater Studios and production company Traverse 32, the film launched across 20+ countries alongside OOH, screenings, and interactive installations, leaving the original tagline's four words entirely unchanged. | N3: cosmetics, personal-care, beauty, documentary, film, entertainment, cinema, ooh, interactive-installation, streaming, tv, france, corporate-purpose, womens-rights, branded-content, social-media
A4: 2025 | B4: Gold | C4: Find Your Friends | D4: Apple | E4: Precision Finding | F4: Apple | G4: United States | H4: B01 - Consumer Goods | I4: digital-presentation-images/film-apple-find-your-friends.webp | J4: vimeo:1068530073 | L4: https://www.lovethework.com/work/entries/find-your-friends-738592 | M4: A film shot at a Star Wars fan convention in which a lone attendee, dressed in Mandalorian armor, uses the Precision Finding feature on his iPhone 15 to locate his friends in a crowd of identically helmeted cosplayers. Designed and released on May 4th as a love letter to the fan community, the film's sound was built at Skywalker Sound and background signage was seeded with details for fans to decode. | N4: smartphone, film, cinema, entertainment, precision-finding, fan-culture, star-wars, cosplay, united-states, sound-design, casting
A5: 2025 | B5: Gold | C5: Never Just a Period | D5: Bodyform | E5: Bodyform | F5: AMV BBDO | G5: United Kingdom | H5: B02 - Healthcare | I5: digital-presentation-images/film-bodyform-never-just-a-period.webp | J5: EQW59KR3c4U | L5: https://www.lovethework.com/work/entries/never-just-a-period-738863 | M5: A film and integrated campaign for Bodyform/Libresse, created by AMV BBDO London, that dramatises the gap between what women are told about their bodies and what they actually experience — staging rarely discussed moments like getting a period while breastfeeding, large perimenopausal clots, and periods that disappear for months after stopping contraception. An online conversation thread prompted audiences with "What do you wish you'd been told?", opening a space for women+ to share experiences spanning first period to last. | N5: femcare, film, cinema, entertainment, integrated-campaign, healthcare, womens-health, social, united-kingdom, menstrual-health, amv-bbdo
A6: 2025 | B6: Gold | C6: Let There Be Cake | D6: KFC Thailand | E6: KFC 40th | F6: Bananas | G6: South Africa | H6: B04 - Travel, Leisure, Retail, Restaurants & Fast-Food Chains | I6: https://ascentialcdn.filespin.io/api/v1/storyboard/880f481b580e4ddbb51427137d8c2233/storyboard_000008.jpg | J6: YDaAgeyVXiw | L6: https://www.lovethework.com/work/entries/let-there-be-cake-759113 | M6: A 40th anniversary film for KFC Thailand that reimagines the brand's milestone as a cake-centric celebration, produced by Bananas Johannesburg and Brains & Brawn Bangkok. The spot uses the visual and ritual language of a birthday cake — candles, layers, the act of cutting — to mark four decades of KFC in Thailand. | N6: qsr, fast-food, restaurant, food, film, cinema, entertainment, brand-anniversary, thailand, birthday, celebration, south-africa
A7: 2025 | B7: Gold | C7: The Last Birthday | D7: Association Valentin Haüy | E7: Non Profit Organization - Defense of the Rights of Blind and Visually Impaired People | F7: Josiane | G7: France | H7: B07 - Not-For-Profit / Charity / Government | I7: digital-presentation-images/film-association-valentin-hauy-the-last-birthday.webp | J7: E4mGmGE8fC0 | L7: https://www.lovethework.com/work/entries/the-last-birthday-739026 | M7: A dark-comedy film set at a birthday party where guests approaching 60 frantically attempt to destroy their own eyesight — scored to Charles Aznavour's "Ces yeux-là" — built to expose a French law that cuts off disability assistance to anyone who loses their sight after age 60. The film was banned from both TV and YouTube before circulating online, produced by Josiane and Hiersoir for the Association Valentin Haüy. | N7: non-profit, online-film, disability-rights, france, public-health, dark-comedy, advocacy, visual-impairment
A8: 2025 | B8: Gold | C8: Telstra - Better on a Better Network | D8: Telstra | E8: Telstra | F8: Bear Meets Eagle on Fire | G8: Australia | H8: F03 - Single-Market Campaign | I8: digital-presentation-images/film-telstra-telstra-better-on-a-better-network.webp | J8: L8wOtakkr28 | L8: https://www.lovethework.com/work/entries/telstra-better-on-a-better-network-739331 | M8: A suite of 26 short films, each set in a different lesser-known regional town or remote area of Australia, brought to life through 56 puppets voiced by 42 actors — each film representing a local story and community that benefits from Telstra's network coverage. The spots aired across Channel 9's Olympics and Paralympics broadcast, replacing the single repeated sponsor spot with a rotating cast of regional characters and landscapes. | N8: telecommunications, film, cinema, entertainment, puppets, craft, regional, australia, broadcast, olympics, sport, multi-spot
A9: 2025 | B9: Gold | C9: The Best Place in the World to Have Herpes | D9: New Zealand Herpes Foundation | E9: New Zealand Herpes Foundation | F9: Finch | G9: Australia | H9: F05 - Use of Humour | I9: digital-presentation-images/film-new-zealand-herpes-foundation-the-best-place-in-the-world-to-have-herpes.webp | J9: vimeo:1081954251 | L9: https://www.lovethework.com/work/entries/the-best-place-in-the-world-to-have-herpes-739431 | M9: A tourism-style campaign for the New Zealand Herpes Foundation, created by Finch in Sydney and Motion Sickness in Auckland, that repositioned herpes stigma reduction as a matter of national pride — framing it as a competition New Zealand could win. A live Herpes Stigma Index on the campaign website tracked New Zealand's ranking against 77 other countries, while a five-lesson "Herpes Destigmatisation Course" used humour to walk participants through misconceptions, awarding points that contributed to the national leaderboard position. The work drew on the fact that 30% of New Zealanders diagnosed with herpes experience depressive or suicidal thoughts, and that the virus — despite being common and largely harmless — is rarely discussed openly. | N9: public-health, digital, health-education, humour, new-zealand, australia, e-learning, website, stigma, ooh
A10: 2025 | B10: Gold | C10: Brian Cox Goes to College | D10: Uber One | E10: Uber One for Students | F10: Special | G10: United States | H10: F05 - Use of Humour | I10: digital-presentation-images/film-uber-one-brian-cox-goes-to-college.webp | J10: vimeo:1035756667 | L10: https://www.lovethework.com/work/entries/brian-cox-goes-to-college-739411 | M10: A TV spot for Uber One's student membership tier that casts 78-year-old Brian Cox — playing a gruff, curmudgeonly version of himself — as an unlikely college student willing to re-enroll just to access $4.99/month perks: $0 delivery fees, 10% off orders, and 6% cash back on rides. The joke is that the deal is so good it makes even a billionaire actor consider going back to campus, with Cox's talent for playing cantankerous authority lending the premise a dry, self-aware irony. | N10: ride-hailing, film, cinema, entertainment, humor, celebrity-casting, student-audience, subscription, united-states, uber-eats, food-delivery, food, restaurant, ecommerce, retail, online-shopping
A11: 2025 | B11: Gold | C11: Group Therapy | D11: AXA | E11: AXA | F11: VML | G11: France | H11: F05 - Use of Humour | I11: digital-presentation-images/film-axa-group-therapy.webp | J11: vimeo:1158349533 | L11: https://www.lovethework.com/work/entries/group-therapy-739424 | M11: A feature-length documentary produced with Kevin Hart's Hartbeat company, in which six comedians — Mike Birbiglia, Nicole Byer, Gary Gulman, London Hughes, Tig Notaro, and Atsuko Okatsuka — participate in a candid group therapy session led by Neil Patrick Harris, built on the insight that comedians routinely process personal pain in front of audiences. Released on Prime Video and supported by a multimedia campaign across Twitch, Fire TV, and Meta, it anchors a global AXA initiative directing viewers to a free Mind Health Self-Check tool — motivated by survey findings that only 4 in 10 people with preventable mental health conditions seek professional help, and that 39% of 18–24 year-olds experience severe anxiety, stress, or depression. | N11: health-insurance, documentary, film, entertainment, cinema, mental-health, healthcare, medical, comedy, prime-video, streaming, tv, global, public-health, branded-content
A12: 2025 | B12: Silver | C12: Flock | D12: Apple | E12: iPhone | F12: TBWA\Media Arts Lab | G12: United States | H12: A01 - Consumer Goods | I12: digital-presentation-images/film-apple-flock.webp | J12: vimeo:1006144786 | L12: https://www.lovethework.com/work/entries/flock-738495 | M12: A dystopian short film, made by TBWA\Media Arts Lab, in which surveillance cameras built to look like birds and bats — pigeons, seagulls, ravens, owls, and bats, each crafted as physical models before being composited into live-action footage — hunt people's browsing data across everyday online moments. Safari's privacy protections intervene to scatter the flock, drawing a contrast between iPhone and browsers that monetize every click, swipe, and scroll. | N12: iphone, consumer-electronics, film, cinema, entertainment, privacy, vfx, creature-design, united-states, safari, online-tracking
A13: 2025 | B13: Silver | C13: Jordan Can't Ban Greatness | D13: Nike | E13: Nike | F13: Wieden+Kennedy | G13: United States | H13: A01 - Consumer Goods | I13: digital-presentation-images/film-nike-jordan-cant-ban-greatness.webp | J13: vimeo:1053855569 | L13: https://www.lovethework.com/work/entries/jordan-cant-ban-greatness-738501 | M13: A staged "ban" rollout launched on NBA Christmas Day 2024, using the 40th anniversary of the NBA's 1985 fine on the Air Jordan I as its premise — asking what the world would look like if Nike had never paid it. Over the following weeks, Jordan Brand's own Instagram account disappeared, Air Jordans were pulled from Nike.com, Jalen Hurts was positioned as fined by the NFL for wearing "unapproved colors," the Jumpman was blacked out on Michael Jordan's Chicago statue, lyrics referencing Air Jordan were removed from Genius, the shoe was banned from NBA2K, a Jordan NASCAR wrap carried a "Banned" theme, and the Jumpman logo was projected into the sky via drone show above the Jordan Brand fan fest in Oakland. | N13: footwear, integrated-campaign, social-media, stunt, sports-marketing, united-states, basketball, film, cinema, entertainment
... A53: 2025 | B53: Bronze | C53: Skin | D53: Raça Magazine | E53: Institutional | F53: LePub | G53: Brazil | H53: F09 - Cultural Engagement | I53: digital-presentation-images/film-raca-magazine-skin.webp | J53: vimeo:1088284685 | L53: https://www.lovethework.com/work/entries/skin-739661 | M53: A print and film ad for RAÇA Magazine, Brazil's Black press publication, built around the handwritten testimony of Carlos Palmeira — a Brazilian man with vitiligo whose skin shifted from completely Black to completely White, a condition affecting 0.009% of Brazilians. His account, written in his own hand and overlaid across his portrait, describes how the same people who once profiled, ignored, or feared him began treating him with warmth as his pigmentation changed — a firsthand account of racism operating through appearance alone. | N53: print, film, cinema, entertainment, magazine, anti-racism, brazil, handwritten, institutional, racial-equity, portrait
A54: 2026 | B54: Gold | C54: Hope | D54: IKEA | E54: IKEA Home Furnishings | F54: TRY | G54: Norway | H54: A01 - Consumer Goods | I54: https://ascentialcdn.filespin.io/api/v1/storyboard/05eb6c2bef6f405cb9e64fa464be0ee5/storyboard_000008.jpg | J54: vimeo:1096194558 | M54: Part of a TRY, Oslo print series for IKEA built on sharp copywriting and art direction, the 'Hope' execution turns an everyday domestic moment into a crafted home-furnishings ad. | N54: ikea, home furnishings, furniture, home, retail, print, copywriting, art direction, design, try, oslo, norway
A55: 2026 | B55: Gold | C55: Mornings | D55: IKEA | E55: IKEA Home Furnishings | F55: TRY | G55: Norway | H55: A01 - Consumer Goods | I55: https://ascentialcdn.filespin.io/api/v1/storyboard/b73a8e6bb7864c92bfc36217a62b9e07/storyboard_000008.jpg | J55: vimeo:1096194558 | M55: Part of a TRY, Oslo print series for IKEA built on sharp copywriting and art direction, the 'Mornings' execution turns an everyday domestic moment into a crafted home-furnishings ad. | N55: ikea, home furnishings, furniture, home, retail, print, copywriting, art direction, design, try, oslo, norway
A56: 2026 | B56: Gold | C56: Picky | D56: IKEA | E56: IKEA Home Furnishings | F56: TRY | G56: Norway | H56: A01 - Consumer Goods | I56: https://ascentialcdn.filespin.io/api/v1/storyboard/0bf25309251246599f87bd442bae7502/storyboard_000008.jpg | J56: vimeo:1096194558 | M56: Part of a TRY, Oslo print series for IKEA built on sharp copywriting and art direction, the 'Picky' execution turns an everyday domestic moment into a crafted home-furnishings ad. | N56: ikea, home furnishings, furniture, home, retail, print, copywriting, art direction, design, try, oslo, norway
A57: 2026 | B57: Gold | C57: Awake | D57: IKEA | E57: IKEA Home Furnishings | F57: TRY | G57: Norway | H57: A01 - Consumer Goods | I57: https://ascentialcdn.filespin.io/api/v1/storyboard/cbd032d6bd4d42cc843cc6b8ae5595f0/storyboard_000008.jpg | J57: vimeo:1096194558 | M57: One of IKEA's run of brand films from TRY built on simple, recognisable moments of life at home, where an everyday domestic scene becomes a quiet reminder of how the home shapes daily life. | N57: ikea, home furnishings, home, family, everyday life, furniture, norway, slice of life
A58: 2026 | B58: Bronze | C58: Slide | D58: Apple | E58: iPhone 17 | F58: Apple | G58: United States | H58: A01 - Consumer Goods | I58: https://i.ytimg.com/vi/PBrYMBacnyM/maxresdefault.jpg | J58: vimeo:1168177137 | L58: https://www.lovethework.com/work/entries/slide-780526 | M58: A demonstration film for the iPhone 17's Ceramic Shield 2 scratch resistance. Across a tense, wordless business negotiation, an iPhone 17 Pro is slid face-down back and forth along a long boardroom table, turning a durability claim into a single sustained piece of tabletop tension. | N58: apple, iphone, smartphone, technology, product demo, durability, screen, negotiation
A59: 2026 | B59: Silver | C59: A Critter Carol | D59: Apple | E59: iPhone | F59: TBWA\Media Arts Lab | G59: United States | H59: A01 - Consumer Goods | I59: https://beastgrip.com/cdn/shop/articles/shot-on-iphone-17-pro-a-critter-carol-beastgrip-gear-behind-the-magic_10ea192b-ee14-4514-915e-2d46daad1ef4.jpg | J59: h7v2YtzPag4 | L59: https://www.lovethework.com/work/entries/a-critter-carol-782154 | M59: Apple's holiday 'Shot on iPhone' film: after a hiker drops an iPhone in a snowy forest, a group of handmade puppet critters — a raccoon, bear, owl, deer and others — find it and film themselves in a joyful musical number celebrating friendship and craft. Directed by Mark Molloy. (Cross-Channel Storytelling entry.) | N59: apple, iphone, smartphone, technology, holiday, christmas, puppets, animation, film, cinema, entertainment, storytelling, cross-channel, music, digital craft, tbwa media arts lab, united states
A60: 2026 | B60: Bronze | C60: Never Over | D60: Eli Lilly | E60: Eli Lilly | F60: Wieden+Kennedy | G60: United States | H60: A02 - Healthcare | I60: https://qtxasset.com/quartz/qcloud5/media/image/lilly-neverover.jpg | J60: CtxdhnieTCQ | L60: https://www.lovethework.com/work/entries/never-over-780835 | M60: A short film that draws a parallel between Olympic sport and scientific research, setting the relentless, never-finished pursuit of athletic greatness against the equally unending work of medical discovery. | N60: eli lilly, pharma, healthcare, olympics, sport, science, research, perseverance
A61: 2026 | B61: Bronze | C61: Good Days | D61: Lilly | E61: Pharma | F61: Wieden+Kennedy | G61: United States | H61: A02 - Healthcare | I61: https://ascentialcdn.filespin.io/api/v1/storyboard/907717afa6174727846d909d942e5a11/storyboard_000008.jpg | J61: vimeo:1150526756 | L61: https://www.lovethework.com/work/entries/good-days-776865 | M61: A short film about Alzheimer's that dramatises the stark, unpredictable contrast between the good and bad days people living with the disease experience, holding the two against each other to convey how much an ordinary good day can mean. | N61: lilly, pharma, healthcare, alzheimers, dementia, memory, caregiving, awareness
